Workbook

Sheet June 25
A1: Date | B1: Task Name | C1: Quantity | D1: RE | E1: Total RE | F1: Start Time | G1: End Time | H1: Actual Time taken | I1: Actual End Time | J1: Break Start Time | K1: Break End Time | L1: Total Break time | M1: Comment | N1: Productivity | O1: 0.1875 | P1: Date | Q1: Total RE | R1: Core | S1: Non-Core | T1: Productivity | U1: 0.33333333
A2: 45810 | B2: OGM - Sizing update | C2: 23 | D2: =IFERROR(VLOOKUP($B2,Task!$B$1:$G$70,6,0)," ") -> 0.0055555556 | E2: =IFERROR(D2*C2," ") -> 0.12777778 | F2: 0.35318287 | G2: 0.51381944 | H2: =IF(G2="","", IF(L2=" ",IF(OR(F2=0,G2=0),"",G2-F2),((G2-F2)-L2))) -> 0.11600694 | I2: =IFERROR(IF(L2=" ",(F2+E2),(F2+E2+L2)),"") -> 0.52559028 | L2: 0.04462963 | N2: =IFERROR(E2/H2," ") -> 1.1014666 | O2: 0.73172454 | P2: =IFERROR(__xludf.DUMMYFUNCTION("UNIQUE($A$2:$A$993)"),45810) -> 45810 | Q2: =SUMIF($A:$A,$P2,$E:$E) -> 0.29444444 | R2: =SUMIF($A:$A,$P2,$H:$H) -> 0.26827546 | S2: =IF(OR(R2="",R2>=$U$1)," ",$U$1-R2) -> 0.06505787 | T2: =IFERROR(AVERAGEIF($A:$A,$P2,$N:$N)," ") -> 1.0954421
A3: 45810 | B3: Wholesale Data Enrichment Report | C3: 1 | D3: =IFERROR(VLOOKUP($B3,Task!$B$1:$G$70,6,0)," ") -> 0.020833333 | E3: =IFERROR(D3*C3," ") -> 0.020833333 | F3: =G2 -> 0.51381944 | G3: 0.53293981 | H3: =IF(G3="","", IF(L3=" ",IF(OR(F3=0,G3=0),"",G3-F3),((G3-F3)-L3))) -> 0.01912037 | I3: =IFERROR(IF(L3=" ",(F3+E3),(F3+E3+L3)),"") -> 0.53465278 | N3: =IFERROR(E3/H3," ") -> 1.0895884 | O3: =O2-O1 -> 0.54422454 | P3: =IFERROR(__xludf.DUMMYFUNCTION("""COMPUTED_VALUE"""),45811) -> 45811 | Q3: =IF(SUMIF($A:$A,$P3,$E:$E)=0,"",SUMIF($A:$A,$P3,$E:$E)) -> 0.27638889 | R3: =IF(SUMIF($A:$A,$P3,$H:$H)=0,"",SUMIF($A:$A,$P3,$H:$H)) -> 0.25203704 | S3: =IF(OR(R3="",R3>=$U$1)," ",$U$1-R3) -> 0.081296296 | T3: =IFERROR(AVERAGEIF($A:$A,$P3,$N:$N)," ") -> 1.0873086
A4: 45810 | B4: Nordstrom SQL DATA Dump | C4: 3 | D4: =IFERROR(VLOOKUP($B4,Task!$B$1:$G$70,6,0)," ") -> 0.048611111 | E4: =IFERROR(D4*C4," ") -> 0.14583333 | F4: =G3 -> 0.53293981 | G4: 0.70162037 | H4: =IF(G4="","", IF(L4=" ",IF(OR(F4=0,G4=0),"",G4-F4),((G4-F4)-L4))) -> 0.13314815 | I4: =IFERROR(IF(L4=" ",(F4+E4),(F4+E4+L4)),"") -> 0.71430556 | L4: 0.035532407 | N4: =IFERROR(E4/H4," ") -> 1.0952712 | P4: =IFERROR(__xludf.DUMMYFUNCTION("""COMPUTED_VALUE"""),45812) -> 45812 | Q4: =IF(SUMIF($A:$A,$P4,$E:$E)=0,"",SUMIF($A:$A,$P4,$E:$E)) -> 0.26111111 | R4: =IF(SUMIF($A:$A,$P4,$H:$H)=0,"",SUMIF($A:$A,$P4,$H:$H)) -> 0.23758102 | S4: =IF(OR(R4="",R4>=$U$1)," ",$U$1-R4) -> 0.095752315 | T4: =IFERROR(AVERAGEIF($A:$A,$P4,$N:$N)," ") -> 1.0985125
A5: 45811 | B5: Nordstrom SQL DATA Dump | C5: 2 | D5: =IFERROR(VLOOKUP($B5,Task!$B$1:$G$70,6,0)," ") -> 0.048611111 | E5: =IFERROR(D5*C5," ") -> 0.097222222 | F5: 0.42399306 | G5: 0.52989016 | H5: =IF(G5="","", IF(L5=" ",IF(OR(F5=0,G5=0),"",G5-F5),((G5-F5)-L5))) -> 0.086614699 | I5: =IFERROR(IF(L5=" ",(F5+E5),(F5+E5+L5)),"") -> 0.54049769 | L5: 0.019282407 | N5: =IFERROR(E5/H5," ") -> 1.1224679 | P5: =IFERROR(__xludf.DUMMYFUNCTION("""COMPUTED_VALUE"""),45813) -> 45813 | Q5: =IF(SUMIF($A:$A,$P5,$E:$E)=0,"",SUMIF($A:$A,$P5,$E:$E)) -> 0.32430556 | R5: =IF(SUMIF($A:$A,$P5,$H:$H)=0,"",SUMIF($A:$A,$P5,$H:$H)) -> 0.29510417 | S5: =IF(OR(R5="",R5>=$U$1)," ",$U$1-R5) -> 0.038229167 | T5: =IFERROR(AVERAGEIF($A:$A,$P5,$N:$N)," ") -> 1.0977707
A6: 45811 | B6: Wholesale Data Enrichment Report | C6: 1 | D6: =IFERROR(VLOOKUP($B6,Task!$B$1:$G$70,6,0)," ") -> 0.020833333 | E6: =IFERROR(D6*C6," ") -> 0.020833333 | F6: =G5 -> 0.52989016 | G6: 0.55974537 | H6: =IF(G6="","", IF(L6=" ",IF(OR(F6=0,G6=0),"",G6-F6),((G6-F6)-L6))) -> 0.020121412 | I6: =IFERROR(IF(L6=" ",(F6+E6),(F6+E6+L6)),"") -> 0.56045729 | L6: 0.0097337963 | N6: =IFERROR(E6/H6," ") -> 1.0353813 | P6: =IFERROR(__xludf.DUMMYFUNCTION("""COMPUTED_VALUE"""),45819) -> 45819 | Q6: =IF(SUMIF($A:$A,$P6,$E:$E)=0,"",SUMIF($A:$A,$P6,$E:$E)) -> 0.34722222 | R6: =IF(SUMIF($A:$A,$P6,$H:$H)=0,"",SUMIF($A:$A,$P6,$H:$H)) -> 0.31711219 | S6: =IF(OR(R6="",R6>=$U$1)," ",$U$1-R6) -> 0.016221146 | T6: =IFERROR(AVERAGEIF($A:$A,$P6,$N:$N)," ") -> 1.090918
A7: 45811 | B7: OGM - Sizing update | C7: 12 | D7: =IFERROR(VLOOKUP($B7,Task!$B$1:$G$70,6,0)," ") -> 0.0055555556 | E7: =IFERROR(D7*C7," ") -> 0.066666667 | F7: =G6 -> 0.55974537 | G7: 0.62164352 | H7: =IF(G7="","", IF(L7=" ",IF(OR(F7=0,G7=0),"",G7-F7),((G7-F7)-L7))) -> 0.061898148 | I7: =IFERROR(IF(L7=" ",(F7+E7),(F7+E7+L7)),"") -> 0.62641204 | N7: =IFERROR(E7/H7," ") -> 1.0770381 | P7: =IFERROR(__xludf.DUMMYFUNCTION("""COMPUTED_VALUE"""),45820) -> 45820 | Q7: =IF(SUMIF($A:$A,$P7,$E:$E)=0,"",SUMIF($A:$A,$P7,$E:$E)) -> 0.30833333 | R7: =IF(SUMIF($A:$A,$P7,$H:$H)=0,"",SUMIF($A:$A,$P7,$H:$H)) -> 0.28547454 | S7: =IF(OR(R7="",R7>=$U$1)," ",$U$1-R7) -> 0.047858796 | T7: =IFERROR(AVERAGEIF($A:$A,$P7,$N:$N)," ") -> 1.0979424
A8: 45811 | B8: OGM - Sizing update | C8: =21-C7 -> 9 | D8: =IFERROR(VLOOKUP($B8,Task!$B$1:$G$70,6,0)," ") -> 0.0055555556 | E8: =IFERROR(D8*C8," ") -> 0.05 | F8: =G7 -> 0.62164352 | G8: 0.69668981 | H8: =IF(G8="","", IF(L8=" ",IF(OR(F8=0,G8=0),"",G8-F8),((G8-F8)-L8))) -> 0.046111111 | I8: =IFERROR(IF(L8=" ",(F8+E8),(F8+E8+L8)),"") -> 0.7005787 | L8: 0.028935185 | N8: =IFERROR(E8/H8," ") -> 1.0843373 | P8: =IFERROR(__xludf.DUMMYFUNCTION("""COMPUTED_VALUE"""),45821) -> 45821 | Q8: =IF(SUMIF($A:$A,$P8,$E:$E)=0,"",SUMIF($A:$A,$P8,$E:$E)) -> 0.34444444 | R8: =IF(SUMIF($A:$A,$P8,$H:$H)=0,"",SUMIF($A:$A,$P8,$H:$H)) -> 0.31457176 | S8: =IF(OR(R8="",R8>=$U$1)," ",$U$1-R8) -> 0.018761574 | T8: =IFERROR(AVERAGEIF($A:$A,$P8,$N:$N)," ") -> 1.0923026
A9: 45811 | B9: DAM - Image Approval | C9: 15 | D9: =IFERROR(VLOOKUP($B9,Task!$B$1:$G$70,6,0)," ") -> 0.0027777778 | E9: =IFERROR(D9*C9," ") -> 0.041666667 | F9: =G8 -> 0.69668981 | G9: 0.73398148 | H9: =IF(G9="","", IF(L9=" ",IF(OR(F9=0,G9=0),"",G9-F9),((G9-F9)-L9))) -> 0.037291667 | I9: =IFERROR(IF(L9=" ",(F9+E9),(F9+E9+L9)),"") -> 0.73835648 | N9: =IFERROR(E9/H9," ") -> 1.1173184 | P9: =IFERROR(__xludf.DUMMYFUNCTION("""COMPUTED_VALUE"""),45824) -> 45824 | Q9: =IF(SUMIF($A:$A,$P9,$E:$E)=0,"",SUMIF($A:$A,$P9,$E:$E)) -> 0.33611111 | R9: =IF(SUMIF($A:$A,$P9,$H:$H)=0,"",SUMIF($A:$A,$P9,$H:$H)) -> 0.30585648 | S9: =IF(OR(R9="",R9>=$U$1)," ",$U$1-R9) -> 0.027476852 | T9: =IFERROR(AVERAGEIF($A:$A,$P9,$N:$N)," ") -> 1.0985607
A10: 45812 | B10: OGM - Sizing update | C10: 7 | D10: =IFERROR(VLOOKUP($B10,Task!$B$1:$G$70,6,0)," ") -> 0.0055555556 | E10: =IFERROR(D10*C10," ") -> 0.038888889 | F10: 0.3659375 | G10: 0.40137731 | H10: =IF(G10="","", IF(L10=" ",IF(OR(F10=0,G10=0),"",G10-F10),((G10-F10)-L10))) -> 0.035439815 | I10: =IFERROR(IF(L10=" ",(F10+E10),(F10+E10+L10)),"") -> 0.40482639 | N10: =IFERROR(E10/H10," ") -> 1.097322 | P10: =IFERROR(__xludf.DUMMYFUNCTION("""COMPUTED_VALUE"""),45825) -> 45825 | Q10: =IF(SUMIF($A:$A,$P10,$E:$E)=0,"",SUMIF($A:$A,$P10,$E:$E)) -> 0.32916667 | R10: =IF(SUMIF($A:$A,$P10,$H:$H)=0,"",SUMIF($A:$A,$P10,$H:$H)) -> 0.29856481 | S10: =IF(OR(R10="",R10>=$U$1)," ",$U$1-R10) -> 0.034768519 | T10: =IFERROR(AVERAGEIF($A:$A,$P10,$N:$N)," ") -> 1.1032726
A11: 45812 | B11: Nordstrom SQL DATA Dump | C11: 1 | D11: =IFERROR(VLOOKUP($B11,Task!$B$1:$G$70,6,0)," ") -> 0.048611111 | E11: =IFERROR(D11*C11," ") -> 0.048611111 | F11: =G10 -> 0.40137731 | G11: 0.50587963 | H11: =IF(G11="","", IF(L11=" ",IF(OR(F11=0,G11=0),"",G11-F11),((G11-F11)-L11))) -> 0.044537037 | I11: =IFERROR(IF(L11=" ",(F11+E11),(F11+E11+L11)),"") -> 0.5099537 | L11: 0.059965278 | N11: =IFERROR(E11/H11," ") -> 1.0914761 | P11: =IFERROR(__xludf.DUMMYFUNCTION("""COMPUTED_VALUE"""),45827) -> 45827 | Q11: =IF(SUMIF($A:$A,$P11,$E:$E)=0,"",SUMIF($A:$A,$P11,$E:$E)) -> 0.35 | R11: =IF(SUMIF($A:$A,$P11,$H:$H)=0,"",SUMIF($A:$A,$P11,$H:$H)) -> 0.32015046 | S11: =IF(OR(R11="",R11>=$U$1)," ",$U$1-R11) -> 0.01318287 | T11: =IFERROR(AVERAGEIF($A:$A,$P11,$N:$N)," ") -> 1.0871975
A12: 45812 | B12: DAM - Image Approval | C12: 35 | D12: =IFERROR(VLOOKUP($B12,Task!$B$1:$G$70,6,0)," ") -> 0.0027777778 | E12: =IFERROR(D12*C12," ") -> 0.097222222 | F12: =G11 -> 0.50587963 | G12: 0.61717593 | H12: =IF(G12="","", IF(L12=" ",IF(OR(F12=0,G12=0),"",G12-F12),((G12-F12)-L12))) -> 0.08837963 | I12: =IFERROR(IF(L12=" ",(F12+E12),(F12+E12+L12)),"") -> 0.62601852 | L12: 0.022916667 | N12: =IFERROR(E12/H12," ") -> 1.1000524 | P12: =IFERROR(__xludf.DUMMYFUNCTION("""COMPUTED_VALUE"""),45828) -> 45828 | Q12: =IF(SUMIF($A:$A,$P12,$E:$E)=0,"",SUMIF($A:$A,$P12,$E:$E)) -> 0.27222222 | R12: =IF(SUMIF($A:$A,$P12,$H:$H)=0,"",SUMIF($A:$A,$P12,$H:$H)) -> 0.2503125 | S12: =IF(OR(R12="",R12>=$U$1)," ",$U$1-R12) -> 0.083020833 | T12: =IFERROR(AVERAGEIF($A:$A,$P12,$N:$N)," ") -> 1.0926938
A13: 45812 | B13: DAM - Image Approval | C13: 20 | D13: =IFERROR(VLOOKUP($B13,Task!$B$1:$G$70,6,0)," ") -> 0.0027777778 | E13: =IFERROR(D13*C13," ") -> 0.055555556 | F13: =G12 -> 0.61717593 | G13: 0.68928241 | H13: =IF(G13="","", IF(L13=" ",IF(OR(F13=0,G13=0),"",G13-F13),((G13-F13)-L13))) -> 0.05025463 | I13: =IFERROR(IF(L13=" ",(F13+E13),(F13+E13+L13)),"") -> 0.69458333 | L13: 0.021851852 | N13: =IFERROR(E13/H13," ") -> 1.1054813 | P13: =IFERROR(__xludf.DUMMYFUNCTION("""COMPUTED_VALUE"""),45831) -> 45831 | Q13: =IF(SUMIF($A:$A,$P13,$E:$E)=0,"",SUMIF($A:$A,$P13,$E:$E)) -> 0.37152778 | R13: =IF(SUMIF($A:$A,$P13,$H:$H)=0,"",SUMIF($A:$A,$P13,$H:$H)) -> 0.33529976 | S13: =IF(OR(R13="",R13>=$U$1)," ",$U$1-R13) | T13: =IFERROR(AVERAGEIF($A:$A,$P13,$N:$N)," ") -> 1.1134048
A14: 45812 | B14: Wholesale Data Enrichment Report | C14: 1 | D14: =IFERROR(VLOOKUP($B14,Task!$B$1:$G$70,6,0)," ") -> 0.020833333 | E14: =IFERROR(D14*C14," ") -> 0.020833333 | F14: =G13 -> 0.68928241 | G14: 0.70825231 | H14: =IF(G14="","", IF(L14=" ",IF(OR(F14=0,G14=0),"",G14-F14),((G14-F14)-L14))) -> 0.018969907 | I14: =IFERROR(IF(L14=" ",(F14+E14),(F14+E14+L14)),"") -> 0.71011574 | N14: =IFERROR(E14/H14," ") -> 1.0982306 | P14: =IFERROR(__xludf.DUMMYFUNCTION("""COMPUTED_VALUE"""),45832) -> 45832 | Q14: =IF(SUMIF($A:$A,$P14,$E:$E)=0,"",SUMIF($A:$A,$P14,$E:$E)) -> 0.25694444 | R14: =IF(SUMIF($A:$A,$P14,$H:$H)=0,"",SUMIF($A:$A,$P14,$H:$H)) -> 0.093796296 | S14: =IF(OR(R14="",R14>=$U$1)," ",$U$1-R14) -> 0.23953704 | T14: =IFERROR(AVERAGEIF($A:$A,$P14,$N:$N)," ") -> 1.1909953
A15: 45813 | B15: Nordstrom SQL DATA Dump | C15: 1 | D15: =IFERROR(VLOOKUP($B15,Task!$B$1:$G$70,6,0)," ") -> 0.048611111 | E15: =IFERROR(D15*C15," ") -> 0.048611111 | F15: 0.38018519 | G15: 0.42590278 | H15: =IF(G15="","", IF(L15=" ",IF(OR(F15=0,G15=0),"",G15-F15),((G15-F15)-L15))) -> 0.045717593 | I15: =IFERROR(IF(L15=" ",(F15+E15),(F15+E15+L15)),"") -> 0.4287963 | N15: =IFERROR(E15/H15," ") -> 1.0632911 | Q15: =IF(SUMIF($A:$A,$P15,$E:$E)=0,"",SUMIF($A:$A,$P15,$E:$E)) | R15: =IF(SUMIF($A:$A,$P15,$H:$H)=0,"",SUMIF($A:$A,$P15,$H:$H)) | S15: =IF(OR(R15="",R15>=$U$1)," ",$U$1-R15) | T15: =IFERROR(AVERAGEIF($A:$A,$P15,$N:$N)," ")
A16: 45813 | B16: OGM - Sizing update | C16: 8 | D16: =IFERROR(VLOOKUP($B16,Task!$B$1:$G$70,6,0)," ") -> 0.0055555556 | E16: =IFERROR(D16*C16," ") -> 0.044444444 | F16: =G15 -> 0.42590278 | G16: 0.46783565 | H16: =IF(G16="","", IF(L16=" ",IF(OR(F16=0,G16=0),"",G16-F16),((G16-F16)-L16))) -> 0.04193287 | I16: =IFERROR(IF(L16=" ",(F16+E16),(F16+E16+L16)),"") -> 0.47034722 | N16: =IFERROR(E16/H16," ") -> 1.0598951 | Q16: =IF(SUMIF($A:$A,$P16,$E:$E)=0,"",SUMIF($A:$A,$P16,$E:$E)) | R16: =IF(SUMIF($A:$A,$P16,$H:$H)=0,"",SUMIF($A:$A,$P16,$H:$H)) | S16: =IF(OR(R16="",R16>=$U$1)," ",$U$1-R16) | T16: =IFERROR(AVERAGEIF($A:$A,$P16,$N:$N)," ")
A17: 45813 | B17: Nordstrom SQL DATA Dump | C17: 1 | D17: =IFERROR(VLOOKUP($B17,Task!$B$1:$G$70,6,0)," ") -> 0.048611111 | E17: =IFERROR(D17*C17," ") -> 0.048611111 | F17: =G16 -> 0.46783565 | G17: 0.53450231 | H17: =IF(G17="","", IF(L17=" ",IF(OR(F17=0,G17=0),"",G17-F17),((G17-F17)-L17))) -> 0.043738426 | I17: =IFERROR(IF(L17=" ",(F17+E17),(F17+E17+L17)),"") -> 0.539375 | L17: 0.022928241 | N17: =IFERROR(E17/H17," ") -> 1.1114051 | Q17: =IF(SUMIF($A:$A,$P17,$E:$E)=0,"",SUMIF($A:$A,$P17,$E:$E)) | R17: =IF(SUMIF($A:$A,$P17,$H:$H)=0,"",SUMIF($A:$A,$P17,$H:$H)) | S17: =IF(OR(R17="",R17>=$U$1)," ",$U$1-R17) | T17: =IFERROR(AVERAGEIF($A:$A,$P17,$N:$N)," ")
A18: 45813 | B18: OGM - Sizing update | C18: 22 | D18: =IFERROR(VLOOKUP($B18,Task!$B$1:$G$70,6,0)," ") -> 0.0055555556 | E18: =IFERROR(D18*C18," ") -> 0.12222222 | F18: =G17 -> 0.53450231 | G18: 0.66586806 | H18: =IF(G18="","", IF(L18=" ",IF(OR(F18=0,G18=0),"",G18-F18),((G18-F18)-L18))) -> 0.10954861 | I18: =IFERROR(IF(L18=" ",(F18+E18),(F18+E18+L18)),"") -> 0.67854167 | L18: 0.02181713 | N18: =IFERROR(E18/H18," ") -> 1.1156894 | Q18: =IF(SUMIF($A:$A,$P18,$E:$E)=0,"",SUMIF($A:$A,$P18,$E:$E)) | R18: =IF(SUMIF($A:$A,$P18,$H:$H)=0,"",SUMIF($A:$A,$P18,$H:$H)) | S18: =IF(OR(R18="",R18>=$U$1)," ",$U$1-R18) | T18: =IFERROR(AVERAGEIF($A:$A,$P18,$N:$N)," ")
A19: 45813 | B19: Wholesale Data Enrichment Report | C19: 1 | D19: =IFERROR(VLOOKUP($B19,Task!$B$1:$G$70,6,0)," ") -> 0.020833333 | E19: =IFERROR(D19*C19," ") -> 0.020833333 | F19: =G18 -> 0.66586806 | G19: 0.6956713 | H19: =IF(G19="","", IF(L19=" ",IF(OR(F19=0,G19=0),"",G19-F19),((G19-F19)-L19))) -> 0.018888889 | I19: =IFERROR(IF(L19=" ",(F19+E19),(F19+E19+L19)),"") -> 0.69761574 | L19: 0.010914352 | N19: =IFERROR(E19/H19," ") -> 1.1029412 | Q19: =IF(SUMIF($A:$A,$P19,$E:$E)=0,"",SUMIF($A:$A,$P19,$E:$E)) | R19: =IF(SUMIF($A:$A,$P19,$H:$H)=0,"",SUMIF($A:$A,$P19,$H:$H)) | S19: =IF(R19=""," ",$U$1-R19) | T19: =IFERROR(AVERAGEIF($A:$A,$P19,$N:$N)," ")
A20: 45813 | B20: WH - Fabric Composition | C20: 15 | D20: =IFERROR(VLOOKUP($B20,Task!$B$1:$G$70,6,0)," ") -> 0.0020833333 | E20: =IFERROR(D20*C20," ") -> 0.03125 | F20: =G19 -> 0.6956713 | G20: 0.72340278 | H20: =IF(G20="","", IF(L20=" ",IF(OR(F20=0,G20=0),"",G20-F20),((G20-F20)-L20))) -> 0.027731481 | I20: =IFERROR(IF(L20=" ",(F20+E20),(F20+E20+L20)),"") -> 0.7269213 | N20: =IFERROR(E20/H20," ") -> 1.1268781 | Q20: =IF(SUMIF($A:$A,$P20,$E:$E)=0,"",SUMIF($A:$A,$P20,$E:$E)) | R20: =IF(SUMIF($A:$A,$P20,$H:$H)=0,"",SUMIF($A:$A,$P20,$H:$H)) | S20: =IF(R20=""," ",$U$1-R20) | T20: =IFERROR(AVERAGEIF($A:$A,$P20,$N:$N)," ")
A21: 45813 | B21: WH - Fabric Composition | C21: 4 | D21: =IFERROR(VLOOKUP($B21,Task!$B$1:$G$70,6,0)," ") -> 0.0020833333 | E21: =IFERROR(D21*C21," ") -> 0.0083333333 | F21: =G20 -> 0.72340278 | G21: 0.74201389 | H21: =IF(G21="","", IF(L21=" ",IF(OR(F21=0,G21=0),"",G21-F21),((G21-F21)-L21))) -> 0.0075462963 | I21: =IFERROR(IF(L21=" ",(F21+E21),(F21+E21+L21)),"") -> 0.74280093 | L21: 0.011064815 | N21: =IFERROR(E21/H21," ") -> 1.1042945 | Q21: =IF(SUMIF($A:$A,$P21,$E:$E)=0,"",SUMIF($A:$A,$P21,$E:$E)) | R21: =IF(SUMIF($A:$A,$P21,$H:$H)=0,"",SUMIF($A:$A,$P21,$H:$H)) | S21: =IF(R21=""," ",$U$1-R21) | T21: =IFERROR(AVERAGEIF($A:$A,$P21,$N:$N)," ")
A22: 45819 | B22: Nordstrom SQL DATA Dump | C22: 1 | D22: =IFERROR(VLOOKUP($B22,Task!$B$1:$G$70,6,0)," ") -> 0.048611111 | E22: =IFERROR(D22*C22," ") -> 0.048611111 | F22: 0.3721875 | G22: 0.41615741 | H22: =IF(G22="","", IF(L22=" ",IF(OR(F22=0,G22=0),"",G22-F22),((G22-F22)-L22))) -> 0.043969907 | I22: =IFERROR(IF(L22=" ",(F22+E22),(F22+E22+L22)),"") -> 0.42079861 | N22: =IFERROR(E22/H22," ") -> 1.1055541 | Q22: =IF(SUMIF($A:$A,$P22,$E:$E)=0,"",SUMIF($A:$A,$P22,$E:$E)) | R22: =IF(SUMIF($A:$A,$P22,$H:$H)=0,"",SUMIF($A:$A,$P22,$H:$H)) | S22: =IF(R22=""," ",$U$1-R22) | T22: =IFERROR(AVERAGEIF($A:$A,$P22,$N:$N)," ")
A23: 45819 | B23: DAM - Image Approval | C23: 24 | D23: =IFERROR(VLOOKUP($B23,Task!$B$1:$G$70,6,0)," ") -> 0.0027777778 | E23: =IFERROR(D23*C23," ") -> 0.066666667 | F23: =G22 -> 0.41615741 | G23: 0.49802083 | H23: =IF(G23="","", IF(L23=" ",IF(OR(F23=0,G23=0),"",G23-F23),((G23-F23)-L23))) -> 0.059872685 | I23: =IFERROR(IF(L23=" ",(F23+E23),(F23+E23+L23)),"") -> 0.50481481 | L23: 0.021990741 | N23: =IFERROR(E23/H23," ") -> 1.1134738 | Q23: =IF(SUMIF($A:$A,$P23,$E:$E)=0,"",SUMIF($A:$A,$P23,$E:$E)) | R23: =IF(SUMIF($A:$A,$P23,$H:$H)=0,"",SUMIF($A:$A,$P23,$H:$H)) | S23: =IF(R23=""," ",$U$1-R23) | T23: =IFERROR(AVERAGEIF($A:$A,$P23,$N:$N)," ")
A24: 45819 | B24: Wholesale Data Enrichment Report | C24: 1 | D24: =IFERROR(VLOOKUP($B24,Task!$B$1:$G$70,6,0)," ") -> 0.020833333 | E24: =IFERROR(D24*C24," ") -> 0.020833333 | F24: =G23 -> 0.49802083 | G24: 0.52861111 | H24: =IF(G24="","", IF(L24=" ",IF(OR(F24=0,G24=0),"",G24-F24),((G24-F24)-L24))) -> 0.019189815 | I24: =IFERROR(IF(L24=" ",(F24+E24),(F24+E24+L24)),"") -> 0.53025463 | L24: 0.011400463 | N24: =IFERROR(E24/H24," ") -> 1.0856454
A25: 45819 | B25: DAM - Image Approval | C25: 22 | D25: =IFERROR(VLOOKUP($B25,Task!$B$1:$G$70,6,0)," ") -> 0.0027777778 | E25: =IFERROR(D25*C25," ") -> 0.061111111 | F25: =G24 -> 0.52861111 | G25: 0.5858912 | H25: =IF(G25="","", IF(L25=" ",IF(OR(F25=0,G25=0),"",G25-F25),((G25-F25)-L25))) -> 0.057280093 | I25: =IFERROR(IF(L25=" ",(F25+E25),(F25+E25+L25)),"") -> 0.58972222 | N25: =IFERROR(E25/H25," ") -> 1.0668822 | P25: C1042
A26: 45819 | B26: DAM - Image Approval | C26: 32 | D26: =IFERROR(VLOOKUP($B26,Task!$B$1:$G$70,6,0)," ") -> 0.0027777778 | E26: =IFERROR(D26*C26," ") -> 0.088888889 | F26: =G25 -> 0.5858912 | G26: 0.68699074 | H26: =IF(G26="","", IF(L26=" ",IF(OR(F26=0,G26=0),"",G26-F26),((G26-F26)-L26))) -> 0.079976852 | I26: =IFERROR(IF(L26=" ",(F26+E26),(F26+E26+L26)),"") -> 0.69590278 | L26: 0.021122685 | N26: =IFERROR(E26/H26," ") -> 1.1114327 | P26: Date | Q26: Core | R26: Break | S26: Other-Idle | T26: Daily Huddle
A27: 45819 | B27: DAM - Image Approval | C27: 6 | D27: =IFERROR(VLOOKUP($B27,Task!$B$1:$G$70,6,0)," ") -> 0.0027777778 | E27: =IFERROR(D27*C27," ") -> 0.016666667 | F27: =G26 -> 0.68699074 | G27: 0.7094213 | H27: =IF(G27="","", IF(L27=" ",IF(OR(F27=0,G27=0),"",G27-F27),((G27-F27)-L27))) -> 0.015439815 | I27: =IFERROR(IF(L27=" ",(F27+E27),(F27+E27+L27)),"") -> 0.71064815 | L27: 0.0069907407 | N27: =IFERROR(E27/H27," ") -> 1.0794603
A28: 45819 | B28: DAM - Image Approval | C28: 16 | D28: =IFERROR(VLOOKUP($B28,Task!$B$1:$G$70,6,0)," ") -> 0.0027777778 | E28: =IFERROR(D28*C28," ") -> 0.044444444 | F28: =G27 -> 0.7094213 | G28: 0.75080432 | H28: =IF(G28="","", IF(L28=" ",IF(OR(F28=0,G28=0),"",G28-F28),((G28-F28)-L28))) -> 0.041383021 | I28: =IFERROR(IF(L28=" ",(F28+E28),(F28+E28+L28)),"") -> 0.75386574 | N28: =IFERROR(E28/H28," ") -> 1.0739778
A29: 45820 | B29: DAM - Image Approval | C29: 18 | D29: =IFERROR(VLOOKUP($B29,Task!$B$1:$G$70,6,0)," ") -> 0.0027777778 | E29: =IFERROR(D29*C29," ") -> 0.05 | F29: 0.3550463 | G29: 0.45251157 | H29: =IF(G29="","", IF(L29=" ",IF(OR(F29=0,G29=0),"",G29-F29),((G29-F29)-L29))) -> 0.045960648 | I29: =IFERROR(IF(L29=" ",(F29+E29),(F29+E29+L29)),"") -> 0.45655093 | L29: 0.05150463 | N29: =IFERROR(E29/H29," ") -> 1.0878872
A30: 45820 | B30: Nordstrom SQL DATA Dump | C30: 1 | D30: =IFERROR(VLOOKUP($B30,Task!$B$1:$G$70,6,0)," ") -> 0.048611111 | E30: =IFERROR(D30*C30," ") -> 0.048611111 | F30: =G29 -> 0.45251157 | G30: 0.52017361 | H30: =IF(G30="","", IF(L30=" ",IF(OR(F30=0,G30=0),"",G30-F30),((G30-F30)-L30))) -> 0.044108796 | I30: =IFERROR(IF(L30=" ",(F30+E30),(F30+E30+L30)),"") -> 0.52467593 | L30: 0.023553241 | N30: =IFERROR(E30/H30," ") -> 1.1020729
A31: 45820 | B31: OGM - Sizing update | C31: 24 | D31: =IFERROR(VLOOKUP($B31,Task!$B$1:$G$70,6,0)," ") -> 0.0055555556 | E31: =IFERROR(D31*C31," ") -> 0.13333333 | F31: =G30 -> 0.52017361 | G31: 0.64217593 | H31: =IF(G31="","", IF(L31=" ",IF(OR(F31=0,G31=0),"",G31-F31),((G31-F31)-L31))) -> 0.12200231 | I31: =IFERROR(IF(L31=" ",(F31+E31),(F31+E31+L31)),"") -> 0.65350694 | N31: =IFERROR(E31/H31," ") -> 1.0928754
A32: 45820 | B32: Nordstrom SQL DATA Dump | C32: 1 | D32: =IFERROR(VLOOKUP($B32,Task!$B$1:$G$70,6,0)," ") -> 0.048611111 | E32: =IFERROR(D32*C32," ") -> 0.048611111 | F32: =G31 -> 0.64217593 | G32: 0.69354167 | H32: =IF(G32="","", IF(L32=" ",IF(OR(F32=0,G32=0),"",G32-F32),((G32-F32)-L32))) -> 0.051365741 | I32: =IFERROR(IF(L32=" ",(F32+E32),(F32+E32+L32)),"") -> 0.69078704 | N32: =IFERROR(E32/H32," ") -> 0.94637224
A33: 45820 | B33: OGM - Sizing update | C33: 5 | D33: =IFERROR(VLOOKUP($B33,Task!$B$1:$G$70,6,0)," ") -> 0.0055555556 | E33: =IFERROR(D33*C33," ") -> 0.027777778 | F33: =G32 -> 0.69354167 | G33: 0.73263889 | H33: =IF(G33="","", IF(L33=" ",IF(OR(F33=0,G33=0),"",G33-F33),((G33-F33)-L33))) -> 0.022037037 | I33: =IFERROR(IF(L33=" ",(F33+E33),(F33+E33+L33)),"") -> 0.73837963 | L33: 0.017060185 | N33: =IFERROR(E33/H33," ") -> 1.2605042
A34: 45821 | B34: Nordstrom SQL DATA Dump | C34: 1 | D34: =IFERROR(VLOOKUP($B34,Task!$B$1:$G$70,6,0)," ") -> 0.048611111 | E34: =IFERROR(D34*C34," ") -> 0.048611111 | F34: 0.3759375 | G34: 0.45972222 | H34: =IF(G34="","", IF(L34=" ",IF(OR(F34=0,G34=0),"",G34-F34),((G34-F34)-L34))) -> 0.043761574 | I34: =IFERROR(IF(L34=" ",(F34+E34),(F34+E34+L34)),"") -> 0.46457176 | L34: 0.040023148 | N34: =IFERROR(E34/H34," ") -> 1.1108172
A35: 45821 | B35: Nordstrom SQL DATA Dump | C35: 1 | D35: =IFERROR(VLOOKUP($B35,Task!$B$1:$G$70,6,0)," ") -> 0.048611111 | E35: =IFERROR(D35*C35," ") -> 0.048611111 | F35: =G34 -> 0.45972222 | G35: 0.5034375 | H35: =IF(G35="","", IF(L35=" ",IF(OR(F35=0,G35=0),"",G35-F35),((G35-F35)-L35))) -> 0.043715278 | I35: =IFERROR(IF(L35=" ",(F35+E35),(F35+E35+L35)),"") -> 0.50833333 | N35: =IFERROR(E35/H35," ") -> 1.1119936
A36: 45821 | B36: Wholesale Data Enrichment Report | C36: 2 | D36: =IFERROR(VLOOKUP($B36,Task!$B$1:$G$70,6,0)," ") -> 0.020833333 | E36: =IFERROR(D36*C36," ") -> 0.041666667 | F36: =G35 -> 0.5034375 | G36: 0.54351852 | H36: =IF(G36="","", IF(L36=" ",IF(OR(F36=0,G36=0),"",G36-F36),((G36-F36)-L36))) -> 0.040081019 | I36: =IFERROR(IF(L36=" ",(F36+E36),(F36+E36+L36)),"") -> 0.54510417 | N36: =IFERROR(E36/H36," ") -> 1.0395611
A37: 45821 | B37: OGM - Sizing update | C37: 17 | D37: =IFERROR(VLOOKUP($B37,Task!$B$1:$G$70,6,0)," ") -> 0.0055555556 | E37: =IFERROR(D37*C37," ") -> 0.094444444 | F37: =G36 -> 0.54351852 | G37: 0.65164352 | H37: =IF(G37="","", IF(L37=" ",IF(OR(F37=0,G37=0),"",G37-F37),((G37-F37)-L37))) -> 0.085185185 | I37: =IFERROR(IF(L37=" ",(F37+E37),(F37+E37+L37)),"") -> 0.66090278 | L37: 0.022939815 | N37: =IFERROR(E37/H37," ") -> 1.1086957
A38: 45821 | B38: DAM - Image Approval | C38: 20 | D38: =IFERROR(VLOOKUP($B38,Task!$B$1:$G$70,6,0)," ") -> 0.0027777778 | E38: =IFERROR(D38*C38," ") -> 0.055555556 | F38: =G37 -> 0.65164352 | G38: 0.70184028 | H38: =IF(G38="","", IF(L38=" ",IF(OR(F38=0,G38=0),"",G38-F38),((G38-F38)-L38))) -> 0.050196759 | I38: =IFERROR(IF(L38=" ",(F38+E38),(F38+E38+L38)),"") -> 0.70719907 | N38: =IFERROR(E38/H38," ") -> 1.1067558
A39: 45821 | B39: OGM - Sizing update | C39: 10 | D39: =IFERROR(VLOOKUP($B39,Task!$B$1:$G$70,6,0)," ") -> 0.0055555556 | E39: =IFERROR(D39*C39," ") -> 0.055555556 | F39: =G38 -> 0.70184028 | G39: 0.75347222 | H39: =IF(G39="","", IF(L39=" ",IF(OR(F39=0,G39=0),"",G39-F39),((G39-F39)-L39))) -> 0.051631944 | I39: =IFERROR(IF(L39=" ",(F39+E39),(F39+E39+L39)),"") -> 0.75739583 | N39: =IFERROR(E39/H39," ") -> 1.0759919
A40: 45824 | B40: OGM - Sizing update | C40: =12-C39 -> 2 | D40: =IFERROR(VLOOKUP($B40,Task!$B$1:$G$70,6,0)," ") -> 0.0055555556 | E40: =IFERROR(D40*C40," ") -> 0.011111111 | F40: 0.39108796 | G40: 0.40119213 | H40: =IF(G40="","", IF(L40=" ",IF(OR(F40=0,G40=0),"",G40-F40),((G40-F40)-L40))) -> 0.010104167 | I40: =IFERROR(IF(L40=" ",(F40+E40),(F40+E40+L40)),"") -> 0.40219907 | N40: =IFERROR(E40/H40," ") -> 1.0996564 | P40: IF(RIGHT(N3,2)="DB","-"&N3,N3)
...

Sheet May 25
A1: Date | B1: Task Name | C1: Quantity | D1: RE | E1: Total RE | F1: Start Time | G1: End Time | H1: Actual Time taken | I1: Actual End Time | J1: Break Start Time | K1: Break End Time | L1: Total Break time | M1: Comment | N1: Productivity | O1: 0.1875 | P1: Date | Q1: Total RE | R1: Core | S1: Non-Core | T1: Productivity | U1: 0.33333333
A2: 45783 | B2: Missing information | C2: 12 | D2: =IFERROR(VLOOKUP($B2,Task!$B$1:$G$70,6,0)," ") -> 0.0083333333 | E2: =IFERROR(D2*C2," ") -> 0.1 | F2: 0.32368056 | G2: 0.41458333 | H2: =IF(G2="","", IF(L2=" ",IF(OR(F2=0,G2=0),"",G2-F2),((G2-F2)-L2))) -> 0.090902778 | I2: =IFERROR(IF(L2=" ",(F2+E2),(F2+E2+L2)),"") -> 0.42368056 | N2: =IFERROR(E2/H2," ") -> 1.1000764 | O2: 0.86133102 | P2: =IFERROR(__xludf.DUMMYFUNCTION("UNIQUE($A$2:$A$993)"),45783) -> 45783 | Q2: =SUMIF($A:$A,$P2,$E:$E) -> 0.31875 | R2: =SUMIF($A:$A,$P2,$H:$H) -> 0.2887963 | S2: =IF(OR(R2="",R2>=$U$1)," ",$U$1-R2) -> 0.044537037 | T2: =IFERROR(AVERAGEIF($A:$A,$P2,$N:$N)," ") -> 1.1023614 | U2: =S2-V2 -> 0.036585648 | V2: 0.0079513889
A3: 45783 | B3: OGM - Sizing update | C3: 10 | D3: =IFERROR(VLOOKUP($B3,Task!$B$1:$G$70,6,0)," ") -> 0.0055555556 | E3: =IFERROR(D3*C3," ") -> 0.055555556 | F3: =G2 -> 0.41458333 | G3: 0.48783565 | H3: =IF(G3="","", IF(L3=" ",IF(OR(F3=0,G3=0),"",G3-F3),((G3-F3)-L3))) -> 0.050462963 | I3: =IFERROR(IF(L3=" ",(F3+E3),(F3+E3+L3)),"") -> 0.49292824 | L3: 0.022789352 | N3: =IFERROR(E3/H3," ") -> 1.1009174 | O3: =O2-O1 -> 0.67383102 | P3: =IFERROR(__xludf.DUMMYFUNCTION("""COMPUTED_VALUE"""),45784) -> 45784 | Q3: =IF(SUMIF($A:$A,$P3,$E:$E)=0,"",SUMIF($A:$A,$P3,$E:$E)) -> 0.31597222 | R3: =IF(SUMIF($A:$A,$P3,$H:$H)=0,"",SUMIF($A:$A,$P3,$H:$H)) -> 0.28361111 | S3: =IF(OR(R3="",R3>=$U$1)," ",$U$1-R3) -> 0.049722222 | T3: =IFERROR(AVERAGEIF($A:$A,$P3,$N:$N)," ") -> 1.1001055
A4: 45783 | B4: Nordstrom SQL DATA Dump | C4: 1 | D4: =IFERROR(VLOOKUP($B4,Task!$B$1:$G$70,6,0)," ") -> 0.048611111 | E4: =IFERROR(D4*C4," ") -> 0.048611111 | F4: =G3 -> 0.48783565 | G4: 0.53212963 | H4: =IF(G4="","", IF(L4=" ",IF(OR(F4=0,G4=0),"",G4-F4),((G4-F4)-L4))) -> 0.044293981 | I4: =IFERROR(IF(L4=" ",(F4+E4),(F4+E4+L4)),"") -> 0.53644676 | N4: =IFERROR(E4/H4," ") -> 1.0974654 | P4: =IFERROR(__xludf.DUMMYFUNCTION("""COMPUTED_VALUE"""),45785) -> 45785 | Q4: =IF(SUMIF($A:$A,$P4,$E:$E)=0,"",SUMIF($A:$A,$P4,$E:$E)) -> 0.34236111 | R4: =IF(SUMIF($A:$A,$P4,$H:$H)=0,"",SUMIF($A:$A,$P4,$H:$H)) -> 0.31034722 | S4: =IF(OR(R4="",R4>=$U$1)," ",$U$1-R4) -> 0.022986111 | T4: =IFERROR(AVERAGEIF($A:$A,$P4,$N:$N)," ") -> 1.1003047
A5: 45783 | B5: WH - Fabric Composition | C5: 55 | D5: =IFERROR(VLOOKUP($B5,Task!$B$1:$G$70,6,0)," ") -> 0.0020833333 | E5: =IFERROR(D5*C5," ") -> 0.11458333 | F5: =G4 -> 0.53212963 | G5: 0.70833333 | H5: =IF(G5="","", IF(L5=" ",IF(OR(F5=0,G5=0),"",G5-F5),((G5-F5)-L5))) -> 0.10313657 | I5: =IFERROR(IF(L5=" ",(F5+E5),(F5+E5+L5)),"") -> 0.71978009 | L5: 0.07306713 | N5: =IFERROR(E5/H5," ") -> 1.1109864 | P5: =IFERROR(__xludf.DUMMYFUNCTION("""COMPUTED_VALUE"""),45786) -> 45786 | Q5: =IF(SUMIF($A:$A,$P5,$E:$E)=0,"",SUMIF($A:$A,$P5,$E:$E)) -> 0.31041667 | R5: =IF(SUMIF($A:$A,$P5,$H:$H)=0,"",SUMIF($A:$A,$P5,$H:$H)) -> 0.28330662 | S5: =IF(OR(R5="",R5>=$U$1)," ",$U$1-R5) -> 0.050026713 | T5: =IFERROR(AVERAGEIF($A:$A,$P5,$N:$N)," ") -> 1.0881073
A6: 45784 | B6: WH - Fabric Composition | C6: 20 | D6: =IFERROR(VLOOKUP($B6,Task!$B$1:$G$70,6,0)," ") -> 0.0020833333 | E6: =IFERROR(D6*C6," ") -> 0.041666667 | F6: 0.33076389 | G6: 0.36851852 | H6: =IF(G6="","", IF(L6=" ",IF(OR(F6=0,G6=0),"",G6-F6),((G6-F6)-L6))) -> 0.03775463 | I6: =IFERROR(IF(L6=" ",(F6+E6),(F6+E6+L6)),"") -> 0.37243056 | N6: =IFERROR(E6/H6," ") -> 1.1036174 | P6: =IFERROR(__xludf.DUMMYFUNCTION("""COMPUTED_VALUE"""),45789) -> 45789 | Q6: =IF(SUMIF($A:$A,$P6,$E:$E)=0,"",SUMIF($A:$A,$P6,$E:$E)) -> 0.35138889 | R6: =IF(SUMIF($A:$A,$P6,$H:$H)=0,"",SUMIF($A:$A,$P6,$H:$H)) -> 0.32054819 | S6: =IF(OR(R6="",R6>=$U$1)," ",$U$1-R6) -> 0.012785139 | T6: =IFERROR(AVERAGEIF($A:$A,$P6,$N:$N)," ") -> 1.095786
A7: 45784 | B7: Nordstrom SQL DATA Dump | C7: 2 | D7: =IFERROR(VLOOKUP($B7,Task!$B$1:$G$70,6,0)," ") -> 0.048611111 | E7: =IFERROR(D7*C7," ") -> 0.097222222 | F7: =G6 -> 0.36851852 | G7: 0.49975694 | H7: =IF(G7="","", IF(L7=" ",IF(OR(F7=0,G7=0),"",G7-F7),((G7-F7)-L7))) -> 0.087210648 | I7: =IFERROR(IF(L7=" ",(F7+E7),(F7+E7+L7)),"") -> 0.50976852 | L7: 0.044027778 | N7: =IFERROR(E7/H7," ") -> 1.1147976 | P7: =IFERROR(__xludf.DUMMYFUNCTION("""COMPUTED_VALUE"""),45790) -> 45790 | Q7: =IF(SUMIF($A:$A,$P7,$E:$E)=0,"",SUMIF($A:$A,$P7,$E:$E)) -> 0.28611111 | R7: =IF(SUMIF($A:$A,$P7,$H:$H)=0,"",SUMIF($A:$A,$P7,$H:$H)) -> 0.26149306 | S7: =IF(OR(R7="",R7>=$U$1)," ",$U$1-R7) -> 0.071840278 | T7: =IFERROR(AVERAGEIF($A:$A,$P7,$N:$N)," ") -> 1.0825554
A8: 45784 | B8: Wholesale Data Enrichment Report | C8: 1 | D8: =IFERROR(VLOOKUP($B8,Task!$B$1:$G$70,6,0)," ") -> 0.020833333 | E8: =IFERROR(D8*C8," ") -> 0.020833333 | F8: =G7 -> 0.49975694 | G8: 0.57866898 | H8: =IF(G8="","", IF(L8=" ",IF(OR(F8=0,G8=0),"",G8-F8),((G8-F8)-L8))) -> 0.020150463 | I8: =IFERROR(IF(L8=" ",(F8+E8),(F8+E8+L8)),"") -> 0.57935185 | L8: 0.058761574 | N8: =IFERROR(E8/H8," ") -> 1.0338886 | P8: =IFERROR(__xludf.DUMMYFUNCTION("""COMPUTED_VALUE"""),45791) -> 45791 | Q8: =IF(SUMIF($A:$A,$P8,$E:$E)=0,"",SUMIF($A:$A,$P8,$E:$E)) -> 0.24166667 | R8: =IF(SUMIF($A:$A,$P8,$H:$H)=0,"",SUMIF($A:$A,$P8,$H:$H)) -> 0.22043981 | S8: =IF(OR(R8="",R8>=$U$1)," ",$U$1-R8) -> 0.11289352 | T8: =IFERROR(AVERAGEIF($A:$A,$P8,$N:$N)," ") -> 1.0964528
A9: 45784 | B9: Training | C9: 1 | D9: =IFERROR(VLOOKUP($B9,Task!$B$1:$G$70,6,0)," ") -> 0.041666667 | E9: =IFERROR(D9*C9," ") -> 0.041666667 | F9: 0.49997685 | G9: 0.53733796 | H9: =IF(G9="","", IF(L9=" ",IF(OR(F9=0,G9=0),"",G9-F9),((G9-F9)-L9))) -> 0.037361111 | I9: =IFERROR(IF(L9=" ",(F9+E9),(F9+E9+L9)),"") -> 0.54164352 | N9: =IFERROR(E9/H9," ") -> 1.1152416 | P9: =IFERROR(__xludf.DUMMYFUNCTION("""COMPUTED_VALUE"""),45792) -> 45792 | Q9: =IF(SUMIF($A:$A,$P9,$E:$E)=0,"",SUMIF($A:$A,$P9,$E:$E)) -> 0.18194444 | R9: =IF(SUMIF($A:$A,$P9,$H:$H)=0,"",SUMIF($A:$A,$P9,$H:$H)) -> 0.16087963 | S9: =IF(OR(R9="",R9>=$U$1)," ",$U$1-R9) -> 0.1724537 | T9: =IFERROR(AVERAGEIF($A:$A,$P9,$N:$N)," ") -> 2.9126799
A10: 45784 | B10: WH - Wash Care update | C10: 55 | D10: =IFERROR(VLOOKUP($B10,Task!$B$1:$G$70,6,0)," ") -> 0.0020833333 | E10: =IFERROR(D10*C10," ") -> 0.11458333 | F10: =G8 -> 0.57866898 | G10: 0.71180556 | H10: =IF(G10="","", IF(L10=" ",IF(OR(F10=0,G10=0),"",G10-F10),((G10-F10)-L10))) -> 0.10113426 | I10: =IFERROR(IF(L10=" ",(F10+E10),(F10+E10+L10)),"") -> 0.72525463 | L10: 0.032002315 | N10: =IFERROR(E10/H10," ") -> 1.1329824 | P10: =IFERROR(__xludf.DUMMYFUNCTION("""COMPUTED_VALUE"""),45793) -> 45793 | Q10: =IF(SUMIF($A:$A,$P10,$E:$E)=0,"",SUMIF($A:$A,$P10,$E:$E)) -> 0.28472222 | R10: =IF(SUMIF($A:$A,$P10,$H:$H)=0,"",SUMIF($A:$A,$P10,$H:$H)) -> 0.26271991 | S10: =IF(OR(R10="",R10>=$U$1)," ",$U$1-R10) -> 0.070613426 | T10: =IFERROR(AVERAGEIF($A:$A,$P10,$N:$N)," ") -> 1.0871626
A11: 45785 | B11: WH - Wash Care update | C11: 71 | D11: =IFERROR(VLOOKUP($B11,Task!$B$1:$G$70,6,0)," ") -> 0.0020833333 | E11: =IFERROR(D11*C11," ") -> 0.14791667 | F11: 0.33653935 | G11: 0.5162037 | H11: =IF(G11="","", IF(L11=" ",IF(OR(F11=0,G11=0),"",G11-F11),((G11-F11)-L11))) -> 0.13459491 | I11: =IFERROR(IF(L11=" ",(F11+E11),(F11+E11+L11)),"") -> 0.52952546 | L11: 0.045069444 | N11: =IFERROR(E11/H11," ") -> 1.0989767 | P11: =IFERROR(__xludf.DUMMYFUNCTION("""COMPUTED_VALUE"""),45796) -> 45796 | Q11: =IF(SUMIF($A:$A,$P11,$E:$E)=0,"",SUMIF($A:$A,$P11,$E:$E)) -> 0.20694444 | R11: =IF(SUMIF($A:$A,$P11,$H:$H)=0,"",SUMIF($A:$A,$P11,$H:$H)) -> 0.18923781 | S11: =IF(OR(R11="",R11>=$U$1)," ",$U$1-R11) -> 0.14409552 | T11: =IFERROR(AVERAGEIF($A:$A,$P11,$N:$N)," ") -> 1.0888777
A12: 45785 | B12: Nordstrom SQL DATA Dump | C12: 1 | D12: =IFERROR(VLOOKUP($B12,Task!$B$1:$G$70,6,0)," ") -> 0.048611111 | E12: =IFERROR(D12*C12," ") -> 0.048611111 | F12: =G11 -> 0.5162037 | G12: 0.56040509 | H12: =IF(G12="","", IF(L12=" ",IF(OR(F12=0,G12=0),"",G12-F12),((G12-F12)-L12))) -> 0.044201389 | I12: =IFERROR(IF(L12=" ",(F12+E12),(F12+E12+L12)),"") -> 0.56481481 | N12: =IFERROR(E12/H12," ") -> 1.0997643 | P12: =IFERROR(__xludf.DUMMYFUNCTION("""COMPUTED_VALUE"""),45797) -> 45797 | Q12: =IF(SUMIF($A:$A,$P12,$E:$E)=0,"",SUMIF($A:$A,$P12,$E:$E)) -> 0.31111111 | R12: =IF(SUMIF($A:$A,$P12,$H:$H)=0,"",SUMIF($A:$A,$P12,$H:$H)) -> 0.27717593 | S12: =IF(OR(R12="",R12>=$U$1)," ",$U$1-R12) -> 0.056157407 | T12: =IFERROR(AVERAGEIF($A:$A,$P12,$N:$N)," ") -> 1.1003696
A13: 45785 | B13: Very Invoice Report | C13: 1 | D13: =IFERROR(VLOOKUP($B13,Task!$B$1:$G$70,6,0)," ") -> 0.020833333 | E13: =IFERROR(D13*C13," ") -> 0.020833333 | F13: =G12 -> 0.56040509 | G13: 0.57950231 | H13: =IF(G13="","", IF(L13=" ",IF(OR(F13=0,G13=0),"",G13-F13),((G13-F13)-L13))) -> 0.019097222 | I13: =IFERROR(IF(L13=" ",(F13+E13),(F13+E13+L13)),"") -> 0.58123843 | N13: =IFERROR(E13/H13," ") -> 1.0909091 | P13: =IFERROR(__xludf.DUMMYFUNCTION("""COMPUTED_VALUE"""),45798) -> 45798 | Q13: =IF(SUMIF($A:$A,$P13,$E:$E)=0,"",SUMIF($A:$A,$P13,$E:$E)) -> 0.24861111 | R13: =IF(SUMIF($A:$A,$P13,$H:$H)=0,"",SUMIF($A:$A,$P13,$H:$H)) -> 0.22947248 | S13: =IF(OR(R13="",R13>=$U$1)," ",$U$1-R13) -> 0.10386086 | T13: =IFERROR(AVERAGEIF($A:$A,$P13,$N:$N)," ") -> 1.0829432
A14: 45785 | B14: WH - Wash Care update | C14: 60 | D14: =IFERROR(VLOOKUP($B14,Task!$B$1:$G$70,6,0)," ") -> 0.0020833333 | E14: =IFERROR(D14*C14," ") -> 0.125 | F14: =G13 -> 0.57950231 | G14: 0.71527778 | H14: =IF(G14="","", IF(L14=" ",IF(OR(F14=0,G14=0),"",G14-F14),((G14-F14)-L14))) -> 0.1124537 | I14: =IFERROR(IF(L14=" ",(F14+E14),(F14+E14+L14)),"") -> 0.72782407 | L14: 0.023321759 | N14: =IFERROR(E14/H14," ") -> 1.1115685 | P14: =IFERROR(__xludf.DUMMYFUNCTION("""COMPUTED_VALUE"""),45799) -> 45799 | Q14: =IF(SUMIF($A:$A,$P14,$E:$E)=0,"",SUMIF($A:$A,$P14,$E:$E)) -> 0.3125 | R14: =IF(SUMIF($A:$A,$P14,$H:$H)=0,"",SUMIF($A:$A,$P14,$H:$H)) -> 0.29038774 | S14: =IF(OR(R14="",R14>=$U$1)," ",$U$1-R14) -> 0.04294559 | T14: =IFERROR(AVERAGEIF($A:$A,$P14,$N:$N)," ") -> 1.0843169
A15: 45786 | B15: WH - Wash Care update | C15: 39 | D15: =IFERROR(VLOOKUP($B15,Task!$B$1:$G$70,6,0)," ") -> 0.0020833333 | E15: =IFERROR(D15*C15," ") -> 0.08125 | F15: 0.34417824 | G15: 0.45226852 | H15: =IF(G15="","", IF(L15=" ",IF(OR(F15=0,G15=0),"",G15-F15),((G15-F15)-L15))) -> 0.074224537 | I15: =IFERROR(IF(L15=" ",(F15+E15),(F15+E15+L15)),"") -> 0.45929398 | L15: 0.033865741 | N15: =IFERROR(E15/H15," ") -> 1.0946515 | P15: =IFERROR(__xludf.DUMMYFUNCTION("""COMPUTED_VALUE"""),45800) -> 45800 | Q15: =IF(SUMIF($A:$A,$P15,$E:$E)=0,"",SUMIF($A:$A,$P15,$E:$E)) -> 0.29027778 | R15: =IF(SUMIF($A:$A,$P15,$H:$H)=0,"",SUMIF($A:$A,$P15,$H:$H)) -> 0.2683912 | S15: =IF(OR(R15="",R15>=$U$1)," ",$U$1-R15) -> 0.06494213 | T15: =IFERROR(AVERAGEIF($A:$A,$P15,$N:$N)," ") -> 1.0690949
A16: 45786 | B16: Nordstrom SQL DATA Dump | C16: 1 | D16: =IFERROR(VLOOKUP($B16,Task!$B$1:$G$70,6,0)," ") -> 0.048611111 | E16: =IFERROR(D16*C16," ") -> 0.048611111 | F16: =G15 -> 0.45226852 | G16: 0.5478125 | H16: =IF(G16="","", IF(L16=" ",IF(OR(F16=0,G16=0),"",G16-F16),((G16-F16)-L16))) -> 0.045648148 | I16: =IFERROR(IF(L16=" ",(F16+E16),(F16+E16+L16)),"") -> 0.55077546 | L16: 0.049895833 | N16: =IFERROR(E16/H16," ") -> 1.0649087 | P16: =IFERROR(__xludf.DUMMYFUNCTION("""COMPUTED_VALUE"""),45804) -> 45804 | Q16: =IF(SUMIF($A:$A,$P16,$E:$E)=0,"",SUMIF($A:$A,$P16,$E:$E)) -> 0.34166667 | R16: =IF(SUMIF($A:$A,$P16,$H:$H)=0,"",SUMIF($A:$A,$P16,$H:$H)) -> 0.31488426 | S16: =IF(OR(R16="",R16>=$U$1)," ",$U$1-R16) -> 0.018449074 | T16: =IFERROR(AVERAGEIF($A:$A,$P16,$N:$N)," ") -> 1.0799339
A17: 45786 | B17: Wholesale Adding Images | C17: 130 | D17: =IFERROR(VLOOKUP($B17,Task!$B$1:$G$70,6,0)," ") -> 0.0013888889 | E17: =IFERROR(D17*C17," ") -> 0.18055556 | F17: =G16 -> 0.5478125 | G17: 0.72227653 | H17: =IF(G17="","", IF(L17=" ",IF(OR(F17=0,G17=0),"",G17-F17),((G17-F17)-L17))) -> 0.16343394 | I17: =IFERROR(IF(L17=" ",(F17+E17),(F17+E17+L17)),"") -> 0.73939815 | L17: 0.011030093 | N17: =IFERROR(E17/H17," ") -> 1.1047617 | P17: =IFERROR(__xludf.DUMMYFUNCTION("""COMPUTED_VALUE"""),45805) -> 45805 | Q17: =IF(SUMIF($A:$A,$P17,$E:$E)=0,"",SUMIF($A:$A,$P17,$E:$E)) -> 0.27777778 | R17: =IF(SUMIF($A:$A,$P17,$H:$H)=0,"",SUMIF($A:$A,$P17,$H:$H)) -> 0.25342801 | S17: =IF(OR(R17="",R17>=$U$1)," ",$U$1-R17) -> 0.079905324 | T17: =IFERROR(AVERAGEIF($A:$A,$P17,$N:$N)," ") -> 1.0972892
A18: 45789 | B18: Nordstrom SQL DATA Dump | C18: 2 | D18: =IFERROR(VLOOKUP($B18,Task!$B$1:$G$70,6,0)," ") -> 0.048611111 | E18: =IFERROR(D18*C18," ") -> 0.097222222 | F18: 0.42283565 | G18: 0.53645833 | H18: =IF(G18="","", IF(L18=" ",IF(OR(F18=0,G18=0),"",G18-F18),((G18-F18)-L18))) -> 0.088356481 | I18: =IFERROR(IF(L18=" ",(F18+E18),(F18+E18+L18)),"") -> 0.54532407 | L18: 0.025266204 | N18: =IFERROR(E18/H18," ") -> 1.1003406 | P18: =IFERROR(__xludf.DUMMYFUNCTION("""COMPUTED_VALUE"""),45806) -> 45806 | Q18: =IF(SUMIF($A:$A,$P18,$E:$E)=0,"",SUMIF($A:$A,$P18,$E:$E)) -> 0.30138889 | R18: =IF(SUMIF($A:$A,$P18,$H:$H)=0,"",SUMIF($A:$A,$P18,$H:$H)) -> 0.27494084 | S18: =IF(OR(R18="",R18>=$U$1)," ",$U$1-R18) -> 0.058392488 | T18: =IFERROR(AVERAGEIF($A:$A,$P18,$N:$N)," ") -> 1.0931463
A19: 45789 | B19: Wholesale Adding Images | C19: 121 | D19: =IFERROR(VLOOKUP($B19,Task!$B$1:$G$70,6,0)," ") -> 0.0013888889 | E19: =IFERROR(D19*C19," ") -> 0.16805556 | F19: =G18 -> 0.53645833 | G19: 0.74722222 | H19: =IF(G19="","", IF(L19=" ",IF(OR(F19=0,G19=0),"",G19-F19),((G19-F19)-L19))) -> 0.15327546 | I19: =IFERROR(IF(L19=" ",(F19+E19),(F19+E19+L19)),"") -> 0.76200231 | L19: 0.057488426 | N19: =IFERROR(E19/H19," ") -> 1.0964283 | P19: =IFERROR(__xludf.DUMMYFUNCTION("""COMPUTED_VALUE"""),45807) -> 45807 | Q19: =IF(SUMIF($A:$A,$P19,$E:$E)=0,"",SUMIF($A:$A,$P19,$E:$E)) -> 0.30277778 | R19: =IF(SUMIF($A:$A,$P19,$H:$H)=0,"",SUMIF($A:$A,$P19,$H:$H)) -> 0.26842593 | S19: =IF(R19=""," ",$U$1-R19) -> 0.064907407 | T19: =IFERROR(AVERAGEIF($A:$A,$P19,$N:$N)," ") -> 1.1002984
A20: 45789 | B20: DAM - Image Approval | C20: 11 | D20: =IFERROR(VLOOKUP($B20,Task!$B$1:$G$70,6,0)," ") -> 0.0027777778 | E20: =IFERROR(D20*C20," ") -> 0.030555556 | F20: 0.64001157 | G20: 0.66778935 | H20: =IF(G20="","", IF(L20=" ",IF(OR(F20=0,G20=0),"",G20-F20),((G20-F20)-L20))) -> 0.027777778 | I20: =IFERROR(IF(L20=" ",(F20+E20),(F20+E20+L20)),"") -> 0.67056713 | N20: =IFERROR(E20/H20," ") -> 1.1 | Q20: =IF(SUMIF($A:$A,$P20,$E:$E)=0,"",SUMIF($A:$A,$P20,$E:$E)) | R20: =IF(SUMIF($A:$A,$P20,$H:$H)=0,"",SUMIF($A:$A,$P20,$H:$H)) | S20: =IF(R20=""," ",$U$1-R20) | T20: =IFERROR(AVERAGEIF($A:$A,$P20,$N:$N)," ")
A21: 45789 | B21: OGM - Sizing update | C21: 10 | D21: =IFERROR(VLOOKUP($B21,Task!$B$1:$G$70,6,0)," ") -> 0.0055555556 | E21: =IFERROR(D21*C21," ") -> 0.055555556 | F21: =G19 -> 0.74722222 | G21: 0.79836069 | H21: =IF(G21="","", IF(L21=" ",IF(OR(F21=0,G21=0),"",G21-F21),((G21-F21)-L21))) -> 0.051138472 | I21: =IFERROR(IF(L21=" ",(F21+E21),(F21+E21+L21)),"") -> 0.80277778 | N21: =IFERROR(E21/H21," ") -> 1.086375 | Q21: =IF(SUMIF($A:$A,$P21,$E:$E)=0,"",SUMIF($A:$A,$P21,$E:$E)) | R21: =IF(SUMIF($A:$A,$P21,$H:$H)=0,"",SUMIF($A:$A,$P21,$H:$H)) | S21: =IF(R21=""," ",$U$1-R21) | T21: =IFERROR(AVERAGEIF($A:$A,$P21,$N:$N)," ")
A22: 45790 | B22: Nordstrom SQL DATA Dump | C22: 3 | D22: =IFERROR(VLOOKUP($B22,Task!$B$1:$G$70,6,0)," ") -> 0.048611111 | E22: =IFERROR(D22*C22," ") -> 0.14583333 | F22: 0.38869213 | G22: 0.57377315 | H22: =IF(G22="","", IF(L22=" ",IF(OR(F22=0,G22=0),"",G22-F22),((G22-F22)-L22))) -> 0.13266204 | I22: =IFERROR(IF(L22=" ",(F22+E22),(F22+E22+L22)),"") -> 0.58694444 | L22: 0.052418981 | N22: =IFERROR(E22/H22," ") -> 1.0992846 | Q22: =IF(SUMIF($A:$A,$P22,$E:$E)=0,"",SUMIF($A:$A,$P22,$E:$E)) | R22: =IF(SUMIF($A:$A,$P22,$H:$H)=0,"",SUMIF($A:$A,$P22,$H:$H)) | S22: =IF(R22=""," ",$U$1-R22) | T22: =IFERROR(AVERAGEIF($A:$A,$P22,$N:$N)," ")
A23: 45790 | B23: DAM - Image Search | C23: 52 | D23: =IFERROR(VLOOKUP($B23,Task!$B$1:$G$70,6,0)," ") -> 0.00069444444 | E23: =IFERROR(D23*C23," ") -> 0.036111111 | F23: =G22 -> 0.57377315 | G23: 0.62552083 | H23: =IF(G23="","", IF(L23=" ",IF(OR(F23=0,G23=0),"",G23-F23),((G23-F23)-L23))) -> 0.032824074 | I23: =IFERROR(IF(L23=" ",(F23+E23),(F23+E23+L23)),"") -> 0.62880787 | L23: 0.018923611 | N23: =IFERROR(E23/H23," ") -> 1.100141 | Q23: =IF(SUMIF($A:$A,$P23,$E:$E)=0,"",SUMIF($A:$A,$P23,$E:$E)) | R23: =IF(SUMIF($A:$A,$P23,$H:$H)=0,"",SUMIF($A:$A,$P23,$H:$H)) | S23: =IF(R23=""," ",$U$1-R23) | T23: =IFERROR(AVERAGEIF($A:$A,$P23,$N:$N)," ")
A24: 45790 | B24: Very Invoice Report | C24: 1 | D24: =IFERROR(VLOOKUP($B24,Task!$B$1:$G$70,6,0)," ") -> 0.020833333 | E24: =IFERROR(D24*C24," ") -> 0.020833333 | F24: =G23 -> 0.62552083 | G24: 0.645625 | H24: =IF(G24="","", IF(L24=" ",IF(OR(F24=0,G24=0),"",G24-F24),((G24-F24)-L24))) -> 0.020104167 | I24: =IFERROR(IF(L24=" ",(F24+E24),(F24+E24+L24)),"") -> 0.64635417 | N24: =IFERROR(E24/H24," ") -> 1.0362694
A25: 45790 | B25: OGM - Sizing update | C25: 10 | D25: =IFERROR(VLOOKUP($B25,Task!$B$1:$G$70,6,0)," ") -> 0.0055555556 | E25: =IFERROR(D25*C25," ") -> 0.055555556 | F25: =G24 -> 0.645625 | G25: 0.71680556 | H25: =IF(G25="","", IF(L25=" ",IF(OR(F25=0,G25=0),"",G25-F25),((G25-F25)-L25))) -> 0.049652778 | I25: =IFERROR(IF(L25=" ",(F25+E25),(F25+E25+L25)),"") -> 0.72270833 | L25: 0.021527778 | N25: =IFERROR(E25/H25," ") -> 1.1188811
A26: 45790 | B26: OGM - Sizing update | C26: 5 | D26: =IFERROR(VLOOKUP($B26,Task!$B$1:$G$70,6,0)," ") -> 0.0055555556 | E26: =IFERROR(D26*C26," ") -> 0.027777778 | F26: =G25 -> 0.71680556 | G26: 0.74305556 | H26: =IF(G26="","", IF(L26=" ",IF(OR(F26=0,G26=0),"",G26-F26),((G26-F26)-L26))) -> 0.02625 | I26: =IFERROR(IF(L26=" ",(F26+E26),(F26+E26+L26)),"") -> 0.74458333 | N26: =IFERROR(E26/H26," ") -> 1.0582011 | P26: Date | Q26: Core | R26: Break | S26: Other-Idle | T26: Daily Huddle
A27: 45791 | B27: OGM - Sizing update | C27: =14-C26 -> 9 | D27: =IFERROR(VLOOKUP($B27,Task!$B$1:$G$70,6,0)," ") -> 0.0055555556 | E27: =IFERROR(D27*C27," ") -> 0.05 | F27: 0.33649306 | G27: 0.38251157 | H27: =IF(G27="","", IF(L27=" ",IF(OR(F27=0,G27=0),"",G27-F27),((G27-F27)-L27))) -> 0.046018519 | I27: =IFERROR(IF(L27=" ",(F27+E27),(F27+E27+L27)),"") -> 0.38649306 | N27: =IFERROR(E27/H27," ") -> 1.0865191
A28: 45791 | B28: Nordstrom SQL DATA Dump | C28: 2 | D28: =IFERROR(VLOOKUP($B28,Task!$B$1:$G$70,6,0)," ") -> 0.048611111 | E28: =IFERROR(D28*C28," ") -> 0.097222222 | F28: =G27 -> 0.38251157 | G28: 0.51979167 | H28: =IF(G28="","", IF(L28=" ",IF(OR(F28=0,G28=0),"",G28-F28),((G28-F28)-L28))) -> 0.088425926 | I28: =IFERROR(IF(L28=" ",(F28+E28),(F28+E28+L28)),"") -> 0.52858796 | L28: 0.048854167 | N28: =IFERROR(E28/H28," ") -> 1.0994764
A29: 45791 | B29: DAM - Image Approval | C29: 5 | D29: =IFERROR(VLOOKUP($B29,Task!$B$1:$G$70,6,0)," ") -> 0.0027777778 | E29: =IFERROR(D29*C29," ") -> 0.013888889 | F29: =G28 -> 0.51979167 | G29: 0.54746157 | H29: =IF(G29="","", IF(L29=" ",IF(OR(F29=0,G29=0),"",G29-F29),((G29-F29)-L29))) -> 0.012600463 | I29: =IFERROR(IF(L29=" ",(F29+E29),(F29+E29+L29)),"") -> 0.54875 | L29: 0.015069444 | N29: =IFERROR(E29/H29," ") -> 1.1022523
A30: 45791 | B30: DAM - Image Approval | C30: 29 | D30: =IFERROR(VLOOKUP($B30,Task!$B$1:$G$70,6,0)," ") -> 0.0027777778 | E30: =IFERROR(D30*C30," ") -> 0.080555556 | F30: =G29 -> 0.54746157 | G30: 0.62928241 | H30: =IF(G30="","", IF(L30=" ",IF(OR(F30=0,G30=0),"",G30-F30),((G30-F30)-L30))) -> 0.073394907 | I30: =IFERROR(IF(L30=" ",(F30+E30),(F30+E30+L30)),"") -> 0.63644306 | L30: 0.0084259259 | N30: =IFERROR(E30/H30," ") -> 1.0975633
A31: 45792 | B31: Nordstrom SQL DATA Dump | C31: 1 | D31: =IFERROR(VLOOKUP($B31,Task!$B$1:$G$70,6,0)," ") -> 0.048611111 | E31: =IFERROR(D31*C31," ") -> 0.048611111 | F31: 0.33915509 | G31: 0.38774306 | H31: =IF(G31="","", IF(L31=" ",IF(OR(F31=0,G31=0),"",G31-F31),((G31-F31)-L31))) -> 0.048587963 | I31: =IFERROR(IF(L31=" ",(F31+E31),(F31+E31+L31)),"") -> 0.3877662 | N31: =IFERROR(E31/H31," ") -> 1.0004764
A32: 45792 | B32: DAM - Image Approval | C32: 38 | D32: =IFERROR(VLOOKUP($B32,Task!$B$1:$G$70,6,0)," ") -> 0.0027777778 | E32: =IFERROR(D32*C32," ") -> 0.10555556 | F32: 0.40388889 | G32: 0.53962963 | H32: =IF(G32="","", IF(L32=" ",IF(OR(F32=0,G32=0),"",G32-F32),((G32-F32)-L32))) -> 0.090798611 | I32: =IFERROR(IF(L32=" ",(F32+E32),(F32+E32+L32)),"") -> 0.55438657 | L32: 0.04494213 | N32: =IFERROR(E32/H32," ") -> 1.1625239
A33: 45792 | B33: OGM - Sizing update | C33: 1 | D33: =IFERROR(VLOOKUP($B33,Task!$B$1:$G$70,6,0)," ") -> 0.0055555556 | E33: =IFERROR(D33*C33," ") -> 0.0055555556 | F33: 0.65172454 | G33: 0.67986111 | H33: =IF(G33="","", IF(L33=" ",IF(OR(F33=0,G33=0),"",G33-F33),((G33-F33)-L33))) -> 0.00065972222 | I33: =IFERROR(IF(L33=" ",(F33+E33),(F33+E33+L33)),"") -> 0.68475694 | L33: 0.027476852 | N33: =IFERROR(E33/H33," ") -> 8.4210526
A34: 45792 | B34: OGM - Sizing update | C34: 4 | D34: =IFERROR(VLOOKUP($B34,Task!$B$1:$G$70,6,0)," ") -> 0.0055555556 | E34: =IFERROR(D34*C34," ") -> 0.022222222 | F34: =G33 -> 0.67986111 | G34: 0.70069444 | H34: =IF(G34="","", IF(L34=" ",IF(OR(F34=0,G34=0),"",G34-F34),((G34-F34)-L34))) -> 0.020833333 | I34: =IFERROR(IF(L34=" ",(F34+E34),(F34+E34+L34)),"") -> 0.70208333 | N34: =IFERROR(E34/H34," ") -> 1.0666667
A35: 45793 | B35: Nordstrom SQL DATA Dump | C35: 1 | D35: =IFERROR(VLOOKUP($B35,Task!$B$1:$G$70,6,0)," ") -> 0.048611111 | E35: =IFERROR(D35*C35," ") -> 0.048611111 | F35: 0.33628472 | G35: 0.42315972 | H35: =IF(G35="","", IF(L35=" ",IF(OR(F35=0,G35=0),"",G35-F35),((G35-F35)-L35))) -> 0.044270833 | I35: =IFERROR(IF(L35=" ",(F35+E35),(F35+E35+L35)),"") -> 0.4275 | L35: 0.042604167 | N35: =IFERROR(E35/H35," ") -> 1.0980392
A36: 45793 | B36: OGM - Sizing update | C36: 20 | D36: =IFERROR(VLOOKUP($B36,Task!$B$1:$G$70,6,0)," ") -> 0.0055555556 | E36: =IFERROR(D36*C36," ") -> 0.11111111 | F36: =G35 -> 0.42315972 | G36: 0.55277778 | H36: =IF(G36="","", IF(L36=" ",IF(OR(F36=0,G36=0),"",G36-F36),((G36-F36)-L36))) -> 0.10155093 | I36: =IFERROR(IF(L36=" ",(F36+E36),(F36+E36+L36)),"") -> 0.56233796 | L36: 0.02806713 | N36: =IFERROR(E36/H36," ") -> 1.0941418
A37: 45793 | B37: WH - Fabric Composition | C37: 60 | D37: =IFERROR(VLOOKUP($B37,Task!$B$1:$G$70,6,0)," ") -> 0.0020833333 | E37: =IFERROR(D37*C37," ") -> 0.125 | F37: =G36 -> 0.55277778 | G37: 0.71527778 | H37: =IF(G37="","", IF(L37=" ",IF(OR(F37=0,G37=0),"",G37-F37),((G37-F37)-L37))) -> 0.11689815 | I37: =IFERROR(IF(L37=" ",(F37+E37),(F37+E37+L37)),"") -> 0.72337963 | L37: 0.045601852 | N37: =IFERROR(E37/H37," ") -> 1.0693069
A38: 45796 | B38: OGM - Sizing update | C38: 21 | D38: =IFERROR(VLOOKUP($B38,Task!$B$1:$G$70,6,0)," ") -> 0.0055555556 | E38: =IFERROR(D38*C38," ") -> 0.11666667 | F38: 0.35261574 | G38: 0.49444444 | H38: =IF(G38="","", IF(L38=" ",IF(OR(F38=0,G38=0),"",G38-F38),((G38-F38)-L38))) -> 0.10606481 | I38: =IFERROR(IF(L38=" ",(F38+E38),(F38+E38+L38)),"") -> 0.5050463 | L38: 0.035763889 | N38: =IFERROR(E38/H38," ") -> 1.0999564
A39: 45796 | B39: Nordstrom SQL DATA Dump | C39: 1 | D39: =IFERROR(VLOOKUP($B39,Task!$B$1:$G$70,6,0)," ") -> 0.048611111 | E39: =IFERROR(D39*C39," ") -> 0.048611111 | F39: =G38 -> 0.49444444 | G39: 0.53919686 | H39: =IF(G39="","", IF(L39=" ",IF(OR(F39=0,G39=0),"",G39-F39),((G39-F39)-L39))) -> 0.044752419 | I39: =IFERROR(IF(L39=" ",(F39+E39),(F39+E39+L39)),"") -> 0.54305556 | N39: =IFERROR(E39/H39," ") -> 1.0862231
A40: 45796 | B40: WH - EAN Update | C40: 15 | D40: =IFERROR(VLOOKUP($B40,Task!$B$1:$G$70,6,0)," ") -> 0.0013888889 | E40: =IFERROR(D40*C40," ") -> 0.020833333 | F40: 0.6005787 | G40: 0.61954326 | H40: =IF(G40="","", IF(L40=" ",IF(OR(F40=0,G40=0),"",G40-F40),((G40-F40)-L40))) -> 0.01896456 | I40: =IFERROR(IF(L40=" ",(F40+E40),(F40+E40+L40)),"") -> 0.62141204 | N40: =IFERROR(E40/H40," ") -> 1.0985403
...

Sheet April 25
A1: Date | B1: Task Name | C1: Quantity | D1: RE | E1: Total RE | F1: Start Time | G1: End Time | H1: Actual Time taken | I1: Actual End Time | J1: Break Start Time | K1: Break End Time | L1: Total Break time | M1: Comment | N1: Productivity | O1: 0.1875 | P1: Date | Q1: Total RE | R1: Core | S1: Non-Core | T1: Productivity | U1: 0.33333333
A2: 45748 | B2: Nordstrom SQL DATA Dump | C2: 1 | D2: =IFERROR(VLOOKUP($B2,Task!$B$1:$G$67,6,0)," ") -> 0.048611111 | E2: =IFERROR(D2*C2," ") -> 0.048611111 | F2: 0.38043981 | G2: 0.42475694 | H2: =IF(G2="","", IF(L2=" ",IF(OR(F2=0,G2=0),"",G2-F2),((G2-F2)-L2))) -> 0.04431713 | I2: =IFERROR(IF(L2=" ",(F2+E2),(F2+E2+L2)),"") -> 0.42905093 | N2: =IFERROR(E2/H2," ") -> 1.0968921 | O2: 0.66658565 | P2: =IFERROR(__xludf.DUMMYFUNCTION("UNIQUE($A$2:$A$993)"),45748) -> 45748 | Q2: =SUMIF($A:$A,$P2,$E:$E) -> 0.35833333 | R2: =SUMIF($A:$A,$P2,$H:$H) -> 0.3275463 | S2: =IF(OR(R2="",R2>=$U$1)," ",$U$1-R2) -> 0.005787037 | T2: =IFERROR(AVERAGEIF($A:$A,$P2,$N:$N)," ") -> 1.0946437 | U2: =S2-V2 -> -0.0021643519 | V2: 0.0079513889
A3: 45748 | B3: Very Invoice Report | C3: 1 | D3: =IFERROR(VLOOKUP($B3,Task!$B$1:$G$67,6,0)," ") -> 0.020833333 | E3: =IFERROR(D3*C3," ") -> 0.020833333 | F3: =G2 -> 0.42475694 | G3: 0.44357639 | H3: =IF(G3="","", IF(L3=" ",IF(OR(F3=0,G3=0),"",G3-F3),((G3-F3)-L3))) -> 0.018819444 | I3: =IFERROR(IF(L3=" ",(F3+E3),(F3+E3+L3)),"") -> 0.44559028 | N3: =IFERROR(E3/H3," ") -> 1.1070111 | O3: =O2-O1 -> 0.47908565 | P3: =IFERROR(__xludf.DUMMYFUNCTION("""COMPUTED_VALUE"""),45749) -> 45749 | Q3: =IF(SUMIF($A:$A,$P3,$E:$E)=0,"",SUMIF($A:$A,$P3,$E:$E)) -> 0.34305556 | R3: =IF(SUMIF($A:$A,$P3,$H:$H)=0,"",SUMIF($A:$A,$P3,$H:$H)) -> 0.31303241 | S3: =IF(OR(R3="",R3>=$U$1)," ",$U$1-R3) -> 0.020300926 | T3: =IFERROR(AVERAGEIF($A:$A,$P3,$N:$N)," ") -> 1.0969028
A4: 45748 | B4: OGM - Sizing update | C4: 8 | D4: =IFERROR(VLOOKUP($B4,Task!$B$1:$G$67,6,0)," ") -> 0.0055555556 | E4: =IFERROR(D4*C4," ") -> 0.044444444 | F4: =G3 -> 0.44357639 | G4: 0.48450231 | H4: =IF(G4="","", IF(L4=" ",IF(OR(F4=0,G4=0),"",G4-F4),((G4-F4)-L4))) -> 0.040925926 | I4: =IFERROR(IF(L4=" ",(F4+E4),(F4+E4+L4)),"") -> 0.48802083 | N4: =IFERROR(E4/H4," ") -> 1.0859729 | P4: =IFERROR(__xludf.DUMMYFUNCTION("""COMPUTED_VALUE"""),45750) -> 45750 | Q4: =IF(SUMIF($A:$A,$P4,$E:$E)=0,"",SUMIF($A:$A,$P4,$E:$E)) -> 0.30555556 | R4: =IF(SUMIF($A:$A,$P4,$H:$H)=0,"",SUMIF($A:$A,$P4,$H:$H)) -> 0.28545139 | S4: =IF(OR(R4="",R4>=$U$1)," ",$U$1-R4) -> 0.047881944 | T4: =IFERROR(AVERAGEIF($A:$A,$P4,$N:$N)," ") -> 1.08548
A5: 45748 | B5: OGM - Sizing update | C5: 12 | D5: =IFERROR(VLOOKUP($B5,Task!$B$1:$G$67,6,0)," ") -> 0.0055555556 | E5: =IFERROR(D5*C5," ") -> 0.066666667 | F5: =G4 -> 0.48450231 | G5: 0.56409722 | H5: =IF(G5="","", IF(L5=" ",IF(OR(F5=0,G5=0),"",G5-F5),((G5-F5)-L5))) -> 0.061585648 | I5: =IFERROR(IF(L5=" ",(F5+E5),(F5+E5+L5)),"") -> 0.56917824 | L5: 0.018009259 | N5: =IFERROR(E5/H5," ") -> 1.0825033 | P5: =IFERROR(__xludf.DUMMYFUNCTION("""COMPUTED_VALUE"""),45751) -> 45751 | Q5: =IF(SUMIF($A:$A,$P5,$E:$E)=0,"",SUMIF($A:$A,$P5,$E:$E)) -> 0.29861111 | R5: =IF(SUMIF($A:$A,$P5,$H:$H)=0,"",SUMIF($A:$A,$P5,$H:$H)) -> 0.27211806 | S5: =IF(OR(R5="",R5>=$U$1)," ",$U$1-R5) -> 0.061215278 | T5: =IFERROR(AVERAGEIF($A:$A,$P5,$N:$N)," ") -> 1.0976166
A6: 45748 | B6: OGM - Sizing update | C6: 15 | D6: =IFERROR(VLOOKUP($B6,Task!$B$1:$G$67,6,0)," ") -> 0.0055555556 | E6: =IFERROR(D6*C6," ") -> 0.083333333 | F6: =G5 -> 0.56409722 | G6: 0.64699074 | H6: =IF(G6="","", IF(L6=" ",IF(OR(F6=0,G6=0),"",G6-F6),((G6-F6)-L6))) -> 0.076331019 | I6: =IFERROR(IF(L6=" ",(F6+E6),(F6+E6+L6)),"") -> 0.65399306 | L6: 0.0065625 | N6: =IFERROR(E6/H6," ") -> 1.0917362 | P6: =IFERROR(__xludf.DUMMYFUNCTION("""COMPUTED_VALUE"""),45754) -> 45754 | Q6: =IF(SUMIF($A:$A,$P6,$E:$E)=0,"",SUMIF($A:$A,$P6,$E:$E)) -> 0.34583333 | R6: =IF(SUMIF($A:$A,$P6,$H:$H)=0,"",SUMIF($A:$A,$P6,$H:$H)) -> 0.32188657 | S6: =IF(OR(R6="",R6>=$U$1)," ",$U$1-R6) -> 0.011446759 | T6: =IFERROR(AVERAGEIF($A:$A,$P6,$N:$N)," ") -> 1.0874699
A7: 45748 | B7: OGM - Sizing update | C7: 17 | D7: =IFERROR(VLOOKUP($B7,Task!$B$1:$G$67,6,0)," ") -> 0.0055555556 | E7: =IFERROR(D7*C7," ") -> 0.094444444 | F7: =G6 -> 0.64699074 | G7: 0.75694444 | H7: =IF(G7="","", IF(L7=" ",IF(OR(F7=0,G7=0),"",G7-F7),((G7-F7)-L7))) -> 0.08556713 | I7: =IFERROR(IF(L7=" ",(F7+E7),(F7+E7+L7)),"") -> 0.76582176 | L7: 0.024386574 | N7: =IFERROR(E7/H7," ") -> 1.1037468 | P7: =IFERROR(__xludf.DUMMYFUNCTION("""COMPUTED_VALUE"""),45755) -> 45755 | Q7: =IF(SUMIF($A:$A,$P7,$E:$E)=0,"",SUMIF($A:$A,$P7,$E:$E)) -> 0.34027778 | R7: =IF(SUMIF($A:$A,$P7,$H:$H)=0,"",SUMIF($A:$A,$P7,$H:$H)) -> 0.31559045 | S7: =IF(OR(R7="",R7>=$U$1)," ",$U$1-R7) -> 0.017742882 | T7: =IFERROR(AVERAGEIF($A:$A,$P7,$N:$N)," ") -> 1.0767588
A8: 45749 | B8: Nordstrom SQL DATA Dump | C8: 1 | D8: =IFERROR(VLOOKUP($B8,Task!$B$1:$G$67,6,0)," ") -> 0.048611111 | E8: =IFERROR(D8*C8," ") -> 0.048611111 | F8: 0.38469907 | G8: 0.42827546 | H8: =IF(G8="","", IF(L8=" ",IF(OR(F8=0,G8=0),"",G8-F8),((G8-F8)-L8))) -> 0.043576389 | I8: =IFERROR(IF(L8=" ",(F8+E8),(F8+E8+L8)),"") -> 0.43331019 | N8: =IFERROR(E8/H8," ") -> 1.1155378 | P8: =IFERROR(__xludf.DUMMYFUNCTION("""COMPUTED_VALUE"""),45756) -> 45756 | Q8: =IF(SUMIF($A:$A,$P8,$E:$E)=0,"",SUMIF($A:$A,$P8,$E:$E)) -> 0.34166667 | R8: =IF(SUMIF($A:$A,$P8,$H:$H)=0,"",SUMIF($A:$A,$P8,$H:$H)) -> 0.32104167 | S8: =IF(OR(R8="",R8>=$U$1)," ",$U$1-R8) -> 0.012291667 | T8: =IFERROR(AVERAGEIF($A:$A,$P8,$N:$N)," ") -> 1.0693352
A9: 45749 | B9: Wholesale Adding Images | C9: 80 | D9: =IFERROR(VLOOKUP($B9,Task!$B$1:$G$67,6,0)," ") -> 0.0013888889 | E9: =IFERROR(D9*C9," ") -> 0.11111111 | F9: =G8 -> 0.42827546 | G9: 0.56319444 | H9: =IF(G9="","", IF(L9=" ",IF(OR(F9=0,G9=0),"",G9-F9),((G9-F9)-L9))) -> 0.10075231 | I9: =IFERROR(IF(L9=" ",(F9+E9),(F9+E9+L9)),"") -> 0.57355324 | L9: 0.034166667 | N9: =IFERROR(E9/H9," ") -> 1.1028145 | P9: =IFERROR(__xludf.DUMMYFUNCTION("""COMPUTED_VALUE"""),45757) -> 45757 | Q9: =IF(SUMIF($A:$A,$P9,$E:$E)=0,"",SUMIF($A:$A,$P9,$E:$E)) -> 0.35 | R9: =IF(SUMIF($A:$A,$P9,$H:$H)=0,"",SUMIF($A:$A,$P9,$H:$H)) -> 0.32435656 | S9: =IF(OR(R9="",R9>=$U$1)," ",$U$1-R9) -> 0.0089767708 | T9: =IFERROR(AVERAGEIF($A:$A,$P9,$N:$N)," ") -> 1.0897232
A10: 45749 | B10: OGM - Sizing update | C10: 9 | D10: =IFERROR(VLOOKUP($B10,Task!$B$1:$G$67,6,0)," ") -> 0.0055555556 | E10: =IFERROR(D10*C10," ") -> 0.05 | F10: =G9 -> 0.56319444 | G10: 0.61888889 | H10: =IF(G10="","", IF(L10=" ",IF(OR(F10=0,G10=0),"",G10-F10),((G10-F10)-L10))) -> 0.046296296 | I10: =IFERROR(IF(L10=" ",(F10+E10),(F10+E10+L10)),"") -> 0.62259259 | L10: 0.0093981481 | N10: =IFERROR(E10/H10," ") -> 1.08 | P10: =IFERROR(__xludf.DUMMYFUNCTION("""COMPUTED_VALUE"""),45758) -> 45758 | Q10: =IF(SUMIF($A:$A,$P10,$E:$E)=0,"",SUMIF($A:$A,$P10,$E:$E)) -> 0.32083333 | R10: =IF(SUMIF($A:$A,$P10,$H:$H)=0,"",SUMIF($A:$A,$P10,$H:$H)) -> 0.29108796 | S10: =IF(OR(R10="",R10>=$U$1)," ",$U$1-R10) -> 0.04224537 | T10: =IFERROR(AVERAGEIF($A:$A,$P10,$N:$N)," ") -> 1.1044141
A11: 45749 | B11: OGM - Sizing update | C11: 24 | D11: =IFERROR(VLOOKUP($B11,Task!$B$1:$G$67,6,0)," ") -> 0.0055555556 | E11: =IFERROR(D11*C11," ") -> 0.13333333 | F11: =G10 -> 0.61888889 | G11: 0.76388889 | H11: =IF(G11="","", IF(L11=" ",IF(OR(F11=0,G11=0),"",G11-F11),((G11-F11)-L11))) -> 0.12240741 | I11: =IFERROR(IF(L11=" ",(F11+E11),(F11+E11+L11)),"") -> 0.77481481 | L11: 0.022592593 | N11: =IFERROR(E11/H11," ") -> 1.0892587 | P11: =IFERROR(__xludf.DUMMYFUNCTION("""COMPUTED_VALUE"""),45761) -> 45761 | Q11: =IF(SUMIF($A:$A,$P11,$E:$E)=0,"",SUMIF($A:$A,$P11,$E:$E)) -> 0.34722222 | R11: =IF(SUMIF($A:$A,$P11,$H:$H)=0,"",SUMIF($A:$A,$P11,$H:$H)) -> 0.32356481 | S11: =IF(OR(R11="",R11>=$U$1)," ",$U$1-R11) -> 0.0097685185 | T11: =IFERROR(AVERAGEIF($A:$A,$P11,$N:$N)," ") -> 1.0805392
A12: 45750 | B12: Nordstrom SQL DATA Dump | C12: 1 | D12: =IFERROR(VLOOKUP($B12,Task!$B$1:$G$67,6,0)," ") -> 0.048611111 | E12: =IFERROR(D12*C12," ") -> 0.048611111 | F12: 0.39038194 | G12: 0.43465278 | H12: =IF(G12="","", IF(L12=" ",IF(OR(F12=0,G12=0),"",G12-F12),((G12-F12)-L12))) -> 0.044270833 | I12: =IFERROR(IF(L12=" ",(F12+E12),(F12+E12+L12)),"") -> 0.43899306 | N12: =IFERROR(E12/H12," ") -> 1.0980392 | P12: =IFERROR(__xludf.DUMMYFUNCTION("""COMPUTED_VALUE"""),45762) -> 45762 | Q12: =IF(SUMIF($A:$A,$P12,$E:$E)=0,"",SUMIF($A:$A,$P12,$E:$E)) -> 0.25694444 | R12: =IF(SUMIF($A:$A,$P12,$H:$H)=0,"",SUMIF($A:$A,$P12,$H:$H)) -> 0.23569457 | S12: =IF(OR(R12="",R12>=$U$1)," ",$U$1-R12) -> 0.097638762 | T12: =IFERROR(AVERAGEIF($A:$A,$P12,$N:$N)," ") -> 1.0888843
A13: 45750 | B13: OGM - Sizing update | C13: =37-C11 -> 13 | D13: =IFERROR(VLOOKUP($B13,Task!$B$1:$G$67,6,0)," ") -> 0.0055555556 | E13: =IFERROR(D13*C13," ") -> 0.072222222 | F13: =G12 -> 0.43465278 | G13: 0.55398148 | H13: =IF(G13="","", IF(L13=" ",IF(OR(F13=0,G13=0),"",G13-F13),((G13-F13)-L13))) -> 0.067824074 | I13: =IFERROR(IF(L13=" ",(F13+E13),(F13+E13+L13)),"") -> 0.55837963 | L13: 0.05150463 | N13: =IFERROR(E13/H13," ") -> 1.0648464 | P13: =IFERROR(__xludf.DUMMYFUNCTION("""COMPUTED_VALUE"""),45763) -> 45763 | Q13: =IF(SUMIF($A:$A,$P13,$E:$E)=0,"",SUMIF($A:$A,$P13,$E:$E)) -> 0.22361111 | R13: =IF(SUMIF($A:$A,$P13,$H:$H)=0,"",SUMIF($A:$A,$P13,$H:$H)) -> 0.20196759 | S13: =IF(OR(R13="",R13>=$U$1)," ",$U$1-R13) -> 0.13136574 | T13: =IFERROR(AVERAGEIF($A:$A,$P13,$N:$N)," ") -> 1.0998741
A14: 45750 | B14: DAM - Image Search | C14: 6 | D14: =IFERROR(VLOOKUP($B14,Task!$B$1:$G$67,6,0)," ") -> 0.00069444444 | E14: =IFERROR(D14*C14," ") -> 0.0041666667 | F14: =G13 -> 0.55398148 | G14: 0.55771991 | H14: =IF(G14="","", IF(L14=" ",IF(OR(F14=0,G14=0),"",G14-F14),((G14-F14)-L14))) -> 0.0037384259 | I14: =IFERROR(IF(L14=" ",(F14+E14),(F14+E14+L14)),"") -> 0.55814815 | N14: =IFERROR(E14/H14," ") -> 1.1145511 | P14: =IFERROR(__xludf.DUMMYFUNCTION("""COMPUTED_VALUE"""),45764) -> 45764 | Q14: =IF(SUMIF($A:$A,$P14,$E:$E)=0,"",SUMIF($A:$A,$P14,$E:$E)) -> 0.34861111 | R14: =IF(SUMIF($A:$A,$P14,$H:$H)=0,"",SUMIF($A:$A,$P14,$H:$H)) -> 0.31748843 | S14: =IF(OR(R14="",R14>=$U$1)," ",$U$1-R14) -> 0.015844907 | T14: =IFERROR(AVERAGEIF($A:$A,$P14,$N:$N)," ") -> 1.0952073
A15: 45750 | B15: DAM - Image Approval | C15: 65 | D15: =IFERROR(VLOOKUP($B15,Task!$B$1:$G$67,6,0)," ") -> 0.0027777778 | E15: =IFERROR(D15*C15," ") -> 0.18055556 | F15: =G14 -> 0.55771991 | G15: 0.77097222 | H15: =IF(G15="","", IF(L15=" ",IF(OR(F15=0,G15=0),"",G15-F15),((G15-F15)-L15))) -> 0.16961806 | I15: =IFERROR(IF(L15=" ",(F15+E15),(F15+E15+L15)),"") -> 0.78190972 | L15: 0.043634259 | N15: =IFERROR(E15/H15," ") -> 1.0644831 | P15: =IFERROR(__xludf.DUMMYFUNCTION("""COMPUTED_VALUE"""),45769) -> 45769 | Q15: =IF(SUMIF($A:$A,$P15,$E:$E)=0,"",SUMIF($A:$A,$P15,$E:$E)) -> 0.35763889 | R15: =IF(SUMIF($A:$A,$P15,$H:$H)=0,"",SUMIF($A:$A,$P15,$H:$H)) -> 0.32353009 | S15: =IF(OR(R15="",R15>=$U$1)," ",$U$1-R15) -> 0.0098032407 | T15: =IFERROR(AVERAGEIF($A:$A,$P15,$N:$N)," ") -> 1.0985691
A16: 45751 | B16: Nordstrom SQL DATA Dump | C16: 1 | D16: =IFERROR(VLOOKUP($B16,Task!$B$1:$G$67,6,0)," ") -> 0.048611111 | E16: =IFERROR(D16*C16," ") -> 0.048611111 | F16: 0.38006944 | G16: 0.47354167 | H16: =IF(G16="","", IF(L16=" ",IF(OR(F16=0,G16=0),"",G16-F16),((G16-F16)-L16))) -> 0.043969907 | I16: =IFERROR(IF(L16=" ",(F16+E16),(F16+E16+L16)),"") -> 0.47818287 | L16: 0.049502315 | N16: =IFERROR(E16/H16," ") -> 1.1055541 | P16: =IFERROR(__xludf.DUMMYFUNCTION("""COMPUTED_VALUE"""),45770) -> 45770 | Q16: =IF(SUMIF($A:$A,$P16,$E:$E)=0,"",SUMIF($A:$A,$P16,$E:$E)) -> 0.35694444 | R16: =IF(SUMIF($A:$A,$P16,$H:$H)=0,"",SUMIF($A:$A,$P16,$H:$H)) -> 0.32287206 | S16: =IF(OR(R16="",R16>=$U$1)," ",$U$1-R16) -> 0.010461273 | T16: =IFERROR(AVERAGEIF($A:$A,$P16,$N:$N)," ") -> 1.150221
A17: 45751 | B17: DAM - Image Approval | C17: 18 | D17: =IFERROR(VLOOKUP($B17,Task!$B$1:$G$67,6,0)," ") -> 0.0027777778 | E17: =IFERROR(D17*C17," ") -> 0.05 | F17: =G16 -> 0.47354167 | G17: 0.56356481 | H17: =IF(G17="","", IF(L17=" ",IF(OR(F17=0,G17=0),"",G17-F17),((G17-F17)-L17))) -> 0.045868056 | I17: =IFERROR(IF(L17=" ",(F17+E17),(F17+E17+L17)),"") -> 0.56769676 | L17: 0.044155093 | N17: =IFERROR(E17/H17," ") -> 1.0900833 | P17: =IFERROR(__xludf.DUMMYFUNCTION("""COMPUTED_VALUE"""),45771) -> 45771 | Q17: =IF(SUMIF($A:$A,$P17,$E:$E)=0,"",SUMIF($A:$A,$P17,$E:$E)) -> 0.32777778 | R17: =IF(SUMIF($A:$A,$P17,$H:$H)=0,"",SUMIF($A:$A,$P17,$H:$H)) -> 0.297139 | S17: =IF(OR(R17="",R17>=$U$1)," ",$U$1-R17) -> 0.036194329 | T17: =IFERROR(AVERAGEIF($A:$A,$P17,$N:$N)," ") -> 1.1016204
